Workbook
Name ExternalData_2: Infopedia!$C$3:$L$31

Sheet Lookup Data
A2: HO1 | B2: 31A
A3: HO1 | B3: 31B
A4: HO1 | B4: 55
A5: HO1 | B5: 65
A6: HO2 | B6: 41
A7: HO2 | B7: 44
A8: HO2 | B8: 46
A9: HO2 | B9: 51
A10: HO3 | B10: 62A
A11: HO3 | B11: 62B
A12: HO3 | B12: 86A
A13: HO3 | B13: 86B
A14: HO4 | B14: 66A
A15: HO4 | B15: 66B
A16: HO4 | B16: 75A
A17: HO4 | B17: 75B
A18: HO4 | B18: 75 ONC
A19: HO4 | B19: 76 ONC
A20: HO5 | B20: 56A
A21: HO5 | B21: 56B
... A23: HO5 | B23: 85B

Sheet Index
B2: 1 | C2: Monday | D2: 0
B3: 2 | C3: Tuesday | D3: 0
B4: 3 | C4: Wednesday | D4: 0
B5: 4 | C5: Thursday | D5: 0
B6: 5 | C6: Friday | D6: 0
B7: 6 | C7: Saturday | D7: 1
B8: 7 | C8: Sunday | D8: 1

Sheet Month
B1: Month | D1: PH?
D2: Day of week | I2: =WEEKDAY(I5,2) -> 2 | J2: =WEEKDAY(J5,2) -> 3 | K2: =WEEKDAY(K5,2) -> 4 | L2: =WEEKDAY(L5,2) -> 5 | M2: =WEEKDAY(M5,2) -> 6 | N2: =WEEKDAY(N5,2) -> 7 | O2: =WEEKDAY(O5,2) -> 1 | P2: =WEEKDAY(P5,2) -> 2 | ... AR2: =WEEKDAY(AR5,2) -> 2
G4: Last cycle | AT4: Calls | AZ4: Calculated | BB4: Cumulative
B5: Name | C5: Team | D5: Ward | E5: Subspec | F5: EligibleShifts | G5: =I5-2 -> 46117 | H5: =I5-1 -> 46118 | I5: 46119 | J5: =I5+1 -> 46120 | K5: =J5+1 -> 46121 | L5: =K5+1 -> 46122 | M5: =L5+1 -> 46123 | N5: =M5+1 -> 46124 | O5: =N5+1 -> 46125 | P5: =O5+1 -> 46126 | Q5: =P5+1 -> 46127 | ... AR5: =AQ5+1 -> 46154 | AT5: Weekday | AU5: Friday/Pre-PH | AV5: Satuday/PH | AW5: Sunday | AX5: WR | AY5: SB | AZ5: # of calls | BA5: Call points | BB5: Call points last month | BC5: Total call points | BD5: Total months | BE5: Avg. points per month
G6: =IFERROR(IF(VLOOKUP($B6,'Month-1'!$B$3:$D$53,2,0)=0,"",VLOOKUP($B6,'Month-1'!$B$3:$D$53,2,0)),"") | H6: =IFERROR(IF(VLOOKUP($B6,'Month-1'!$B$3:$D$53,3,0)=0,"",VLOOKUP($B7,'Month-1'!$B$3:$D$53,3,0)),"") | AT6: =COUNTIFS(I6:AR6,"MO*",$I$2:$AR$2,"<5",$I$1:$AR$1,"<>PRE", $I$1:$AR$1,"<>Y") -> 0 | AU6: =COUNTIFS(I6:AR6,"MO*",$I$1:$AR$1,"PRE")+COUNTIFS(I6:AR6,"MO*",$I$2:$AR$2,"5",$I$1:$AR$1,"<>PRE",$I$1:$AR$1,"<>Y") -> 0 | AV6: =COUNTIFS(I6:AR6,"MO*",$I$1:$AR$1,"Y")+COUNTIFS(I6:AR6,"MO*",$I$2:$AR$2,"6",$I$1:$AR$1,"<>PRE",$I$1:$AR$1,"<>Y") -> 0 | AW6: =COUNTIFS(I6:AR6,"MO*", $I$2:$AR$2,"7",$I$1:$AR$1,"<>PRE", $I$1:$AR$1,"<>Y") -> 0 | AX6: =COUNTIF(I6:AR6,"WR*") -> 0 | AY6: =COUNTIF(I6:AR6,"SB") -> 0 | AZ6: =SUM(AT6:AW6) -> 0 | BA6: =AT6*1+AU6*3+AV6*4+AW6*3 -> 0 | BB6: =IFERROR(INDEX('Month-1'!$F$3:$F$53,MATCH($B6,'Month-1'!$B$3:$B$53,0)),0) -> 0 | BC6: =BA6+BB6 -> 0 | BD6: =IFERROR(INDEX('Month-1'!$G$3:$G$53,MATCH($B6,'Month-1'!$B$3:$B$53,0)),0) + 1 -> 1 | BE6: =BC6/BD6 -> 0
G7: =IFERROR(IF(VLOOKUP($B7,'Month-1'!$B$3:$D$53,2,0)=0,"",VLOOKUP($B7,'Month-1'!$B$3:$D$53,2,0)),"") | H7: =IFERROR(IF(VLOOKUP($B7,'Month-1'!$B$3:$D$53,3,0)=0,"",VLOOKUP($B8,'Month-1'!$B$3:$D$53,3,0)),"") | AT7: =COUNTIFS(I7:AR7,"MO*",$I$2:$AR$2,"<5",$I$1:$AR$1,"<>PRE", $I$1:$AR$1,"<>Y") -> 0 | AU7: =COUNTIFS(I7:AR7,"MO*",$I$1:$AR$1,"PRE")+COUNTIFS(I7:AR7,"MO*",$I$2:$AR$2,"5",$I$1:$AR$1,"<>PRE",$I$1:$AR$1,"<>Y") -> 0 | AV7: =COUNTIFS(I7:AR7,"MO*",$I$1:$AR$1,"Y")+COUNTIFS(I7:AR7,"MO*",$I$2:$AR$2,"6",$I$1:$AR$1,"<>PRE",$I$1:$AR$1,"<>Y") -> 0 | AW7: =COUNTIFS(I7:AR7,"MO*", $I$2:$AR$2,"7",$I$1:$AR$1,"<>PRE", $I$1:$AR$1,"<>Y") -> 0 | AX7: =COUNTIF(I7:AR7,"WR*") -> 0 | AY7: =COUNTIF(I7:AR7,"SB") -> 0 | AZ7: =SUM(AT7:AW7) -> 0 | BA7: =AT7*1+AU7*3+AV7*4+AW7*3 -> 0 | BB7: =IFERROR(INDEX('Month-1'!$F$3:$F$53,MATCH($B7,'Month-1'!$B$3:$B$53,0)),0) -> 0 | BC7: =BA7+BB7 -> 0 | BD7: =IFERROR(INDEX('Month-1'!$G$3:$G$53,MATCH($B7,'Month-1'!$B$3:$B$53,0)),0) + 1 -> 1 | BE7: =BC7/BD7 -> 0
G8: =IFERROR(IF(VLOOKUP($B8,'Month-1'!$B$3:$D$53,2,0)=0,"",VLOOKUP($B8,'Month-1'!$B$3:$D$53,2,0)),"") | H8: =IFERROR(IF(VLOOKUP($B8,'Month-1'!$B$3:$D$53,3,0)=0,"",VLOOKUP($B9,'Month-1'!$B$3:$D$53,3,0)),"") | AT8: =COUNTIFS(I8:AR8,"MO*",$I$2:$AR$2,"<5",$I$1:$AR$1,"<>PRE", $I$1:$AR$1,"<>Y") -> 0 | AU8: =COUNTIFS(I8:AR8,"MO*",$I$1:$AR$1,"PRE")+COUNTIFS(I8:AR8,"MO*",$I$2:$AR$2,"5",$I$1:$AR$1,"<>PRE",$I$1:$AR$1,"<>Y") -> 0 | AV8: =COUNTIFS(I8:AR8,"MO*",$I$1:$AR$1,"Y")+COUNTIFS(I8:AR8,"MO*",$I$2:$AR$2,"6",$I$1:$AR$1,"<>PRE",$I$1:$AR$1,"<>Y") -> 0 | AW8: =COUNTIFS(I8:AR8,"MO*", $I$2:$AR$2,"7",$I$1:$AR$1,"<>PRE", $I$1:$AR$1,"<>Y") -> 0 | AX8: =COUNTIF(I8:AR8,"WR*") -> 0 | AY8: =COUNTIF(I8:AR8,"SB") -> 0 | AZ8: =SUM(AT8:AW8) -> 0 | BA8: =AT8*1+AU8*3+AV8*4+AW8*3 -> 0 | BB8: =IFERROR(INDEX('Month-1'!$F$3:$F$53,MATCH($B8,'Month-1'!$B$3:$B$53,0)),0) -> 0 | BC8: =BA8+BB8 -> 0 | BD8: =IFERROR(INDEX('Month-1'!$G$3:$G$53,MATCH($B8,'Month-1'!$B$3:$B$53,0)),0) + 1 -> 1 | BE8: =BC8/BD8 -> 0
G9: =IFERROR(IF(VLOOKUP($B9,'Month-1'!$B$3:$D$53,2,0)=0,"",VLOOKUP($B9,'Month-1'!$B$3:$D$53,2,0)),"") | H9: =IFERROR(IF(VLOOKUP($B9,'Month-1'!$B$3:$D$53,3,0)=0,"",VLOOKUP($B10,'Month-1'!$B$3:$D$53,3,0)),"") | AT9: =COUNTIFS(I9:AR9,"MO*",$I$2:$AR$2,"<5",$I$1:$AR$1,"<>PRE", $I$1:$AR$1,"<>Y") -> 0 | AU9: =COUNTIFS(I9:AR9,"MO*",$I$1:$AR$1,"PRE")+COUNTIFS(I9:AR9,"MO*",$I$2:$AR$2,"5",$I$1:$AR$1,"<>PRE",$I$1:$AR$1,"<>Y") -> 0 | AV9: =COUNTIFS(I9:AR9,"MO*",$I$1:$AR$1,"Y")+COUNTIFS(I9:AR9,"MO*",$I$2:$AR$2,"6",$I$1:$AR$1,"<>PRE",$I$1:$AR$1,"<>Y") -> 0 | AW9: =COUNTIFS(I9:AR9,"MO*", $I$2:$AR$2,"7",$I$1:$AR$1,"<>PRE", $I$1:$AR$1,"<>Y") -> 0 | AX9: =COUNTIF(I9:AR9,"WR*") -> 0 | AY9: =COUNTIF(I9:AR9,"SB") -> 0 | AZ9: =SUM(AT9:AW9) -> 0 | BA9: =AT9*1+AU9*3+AV9*4+AW9*3 -> 0 | BB9: =IFERROR(INDEX('Month-1'!$F$3:$F$53,MATCH($B9,'Month-1'!$B$3:$B$53,0)),0) -> 0 | BC9: =BA9+BB9 -> 0 | BD9: =IFERROR(INDEX('Month-1'!$G$3:$G$53,MATCH($B9,'Month-1'!$B$3:$B$53,0)),0) + 1 -> 1 | BE9: =BC9/BD9 -> 0
G10: =IFERROR(IF(VLOOKUP($B10,'Month-1'!$B$3:$D$53,2,0)=0,"",VLOOKUP($B10,'Month-1'!$B$3:$D$53,2,0)),"") | H10: =IFERROR(IF(VLOOKUP($B10,'Month-1'!$B$3:$D$53,3,0)=0,"",VLOOKUP($B11,'Month-1'!$B$3:$D$53,3,0)),"") | AT10: =COUNTIFS(I10:AR10,"MO*",$I$2:$AR$2,"<5",$I$1:$AR$1,"<>PRE", $I$1:$AR$1,"<>Y") -> 0 | AU10: =COUNTIFS(I10:AR10,"MO*",$I$1:$AR$1,"PRE")+COUNTIFS(I10:AR10,"MO*",$I$2:$AR$2,"5",$I$1:$AR$1,"<>PRE",$I$1:$AR$1,"<>Y") -> 0 | AV10: =COUNTIFS(I10:AR10,"MO*",$I$1:$AR$1,"Y")+COUNTIFS(I10:AR10,"MO*",$I$2:$AR$2,"6",$I$1:$AR$1,"<>PRE",$I$1:$AR$1,"<>Y") -> 0 | AW10: =COUNTIFS(I10:AR10,"MO*", $I$2:$AR$2,"7",$I$1:$AR$1,"<>PRE", $I$1:$AR$1,"<>Y") -> 0 | AX10: =COUNTIF(I10:AR10,"WR*") -> 0 | AY10: =COUNTIF(I10:AR10,"SB") -> 0 | AZ10: =SUM(AT10:AW10) -> 0 | BA10: =AT10*1+AU10*3+AV10*4+AW10*3 -> 0 | BB10: =IFERROR(INDEX('Month-1'!$F$3:$F$53,MATCH($B10,'Month-1'!$B$3:$B$53,0)),0) -> 0 | BC10: =BA10+BB10 -> 0 | BD10: =IFERROR(INDEX('Month-1'!$G$3:$G$53,MATCH($B10,'Month-1'!$B$3:$B$53,0)),0) + 1 -> 1 | BE10: =BC10/BD10 -> 0
G11: =IFERROR(IF(VLOOKUP($B11,'Month-1'!$B$3:$D$53,2,0)=0,"",VLOOKUP($B11,'Month-1'!$B$3:$D$53,2,0)),"") | H11: =IFERROR(IF(VLOOKUP($B11,'Month-1'!$B$3:$D$53,3,0)=0,"",VLOOKUP($B12,'Month-1'!$B$3:$D$53,3,0)),"") | AT11: =COUNTIFS(I11:AR11,"MO*",$I$2:$AR$2,"<5",$I$1:$AR$1,"<>PRE", $I$1:$AR$1,"<>Y") -> 0 | AU11: =COUNTIFS(I11:AR11,"MO*",$I$1:$AR$1,"PRE")+COUNTIFS(I11:AR11,"MO*",$I$2:$AR$2,"5",$I$1:$AR$1,"<>PRE",$I$1:$AR$1,"<>Y") -> 0 | AV11: =COUNTIFS(I11:AR11,"MO*",$I$1:$AR$1,"Y")+COUNTIFS(I11:AR11,"MO*",$I$2:$AR$2,"6",$I$1:$AR$1,"<>PRE",$I$1:$AR$1,"<>Y") -> 0 | AW11: =COUNTIFS(I11:AR11,"MO*", $I$2:$AR$2,"7",$I$1:$AR$1,"<>PRE", $I$1:$AR$1,"<>Y") -> 0 | AX11: =COUNTIF(I11:AR11,"WR*") -> 0 | AY11: =COUNTIF(I11:AR11,"SB") -> 0 | AZ11: =SUM(AT11:AW11) -> 0 | BA11: =AT11*1+AU11*3+AV11*4+AW11*3 -> 0 | BB11: =IFERROR(INDEX('Month-1'!$F$3:$F$53,MATCH($B11,'Month-1'!$B$3:$B$53,0)),0) -> 0 | BC11: =BA11+BB11 -> 0 | BD11: =IFERROR(INDEX('Month-1'!$G$3:$G$53,MATCH($B11,'Month-1'!$B$3:$B$53,0)),0) + 1 -> 1 | BE11: =BC11/BD11 -> 0
G12: =IFERROR(IF(VLOOKUP($B12,'Month-1'!$B$3:$D$53,2,0)=0,"",VLOOKUP($B12,'Month-1'!$B$3:$D$53,2,0)),"") | H12: =IFERROR(IF(VLOOKUP($B12,'Month-1'!$B$3:$D$53,3,0)=0,"",VLOOKUP($B13,'Month-1'!$B$3:$D$53,3,0)),"") | AT12: =COUNTIFS(I12:AR12,"MO*",$I$2:$AR$2,"<5",$I$1:$AR$1,"<>PRE", $I$1:$AR$1,"<>Y") -> 0 | AU12: =COUNTIFS(I12:AR12,"MO*",$I$1:$AR$1,"PRE")+COUNTIFS(I12:AR12,"MO*",$I$2:$AR$2,"5",$I$1:$AR$1,"<>PRE",$I$1:$AR$1,"<>Y") -> 0 | AV12: =COUNTIFS(I12:AR12,"MO*",$I$1:$AR$1,"Y")+COUNTIFS(I12:AR12,"MO*",$I$2:$AR$2,"6",$I$1:$AR$1,"<>PRE",$I$1:$AR$1,"<>Y") -> 0 | AW12: =COUNTIFS(I12:AR12,"MO*", $I$2:$AR$2,"7",$I$1:$AR$1,"<>PRE", $I$1:$AR$1,"<>Y") -> 0 | AX12: =COUNTIF(I12:AR12,"WR*") -> 0 | AY12: =COUNTIF(I12:AR12,"SB") -> 0 | AZ12: =SUM(AT12:AW12) -> 0 | BA12: =AT12*1+AU12*3+AV12*4+AW12*3 -> 0 | BB12: =IFERROR(INDEX('Month-1'!$F$3:$F$53,MATCH($B12,'Month-1'!$B$3:$B$53,0)),0) -> 0 | BC12: =BA12+BB12 -> 0 | BD12: =IFERROR(INDEX('Month-1'!$G$3:$G$53,MATCH($B12,'Month-1'!$B$3:$B$53,0)),0) + 1 -> 1 | BE12: =BC12/BD12 -> 0
G13: =IFERROR(IF(VLOOKUP($B13,'Month-1'!$B$3:$D$53,2,0)=0,"",VLOOKUP($B13,'Month-1'!$B$3:$D$53,2,0)),"") | H13: =IFERROR(IF(VLOOKUP($B13,'Month-1'!$B$3:$D$53,3,0)=0,"",VLOOKUP($B14,'Month-1'!$B$3:$D$53,3,0)),"") | AT13: =COUNTIFS(I13:AR13,"MO*",$I$2:$AR$2,"<5",$I$1:$AR$1,"<>PRE", $I$1:$AR$1,"<>Y") -> 0 | AU13: =COUNTIFS(I13:AR13,"MO*",$I$1:$AR$1,"PRE")+COUNTIFS(I13:AR13,"MO*",$I$2:$AR$2,"5",$I$1:$AR$1,"<>PRE",$I$1:$AR$1,"<>Y") -> 0 | AV13: =COUNTIFS(I13:AR13,"MO*",$I$1:$AR$1,"Y")+COUNTIFS(I13:AR13,"MO*",$I$2:$AR$2,"6",$I$1:$AR$1,"<>PRE",$I$1:$AR$1,"<>Y") -> 0 | AW13: =COUNTIFS(I13:AR13,"MO*", $I$2:$AR$2,"7",$I$1:$AR$1,"<>PRE", $I$1:$AR$1,"<>Y") -> 0 | AX13: =COUNTIF(I13:AR13,"WR*") -> 0 | AY13: =COUNTIF(I13:AR13,"SB") -> 0 | AZ13: =SUM(AT13:AW13) -> 0 | BA13: =AT13*1+AU13*3+AV13*4+AW13*3 -> 0 | BB13: =IFERROR(INDEX('Month-1'!$F$3:$F$53,MATCH($B13,'Month-1'!$B$3:$B$53,0)),0) -> 0 | BC13: =BA13+BB13 -> 0 | BD13: =IFERROR(INDEX('Month-1'!$G$3:$G$53,MATCH($B13,'Month-1'!$B$3:$B$53,0)),0) + 1 -> 1 | BE13: =BC13/BD13 -> 0
G14: =IFERROR(IF(VLOOKUP($B14,'Month-1'!$B$3:$D$53,2,0)=0,"",VLOOKUP($B14,'Month-1'!$B$3:$D$53,2,0)),"") | H14: =IFERROR(IF(VLOOKUP($B14,'Month-1'!$B$3:$D$53,3,0)=0,"",VLOOKUP($B15,'Month-1'!$B$3:$D$53,3,0)),"") | AT14: =COUNTIFS(I14:AR14,"MO*",$I$2:$AR$2,"<5",$I$1:$AR$1,"<>PRE", $I$1:$AR$1,"<>Y") -> 0 | AU14: =COUNTIFS(I14:AR14,"MO*",$I$1:$AR$1,"PRE")+COUNTIFS(I14:AR14,"MO*",$I$2:$AR$2,"5",$I$1:$AR$1,"<>PRE",$I$1:$AR$1,"<>Y") -> 0 | AV14: =COUNTIFS(I14:AR14,"MO*",$I$1:$AR$1,"Y")+COUNTIFS(I14:AR14,"MO*",$I$2:$AR$2,"6",$I$1:$AR$1,"<>PRE",$I$1:$AR$1,"<>Y") -> 0 | AW14: =COUNTIFS(I14:AR14,"MO*", $I$2:$AR$2,"7",$I$1:$AR$1,"<>PRE", $I$1:$AR$1,"<>Y") -> 0 | AX14: =COUNTIF(I14:AR14,"WR*") -> 0 | AY14: =COUNTIF(I14:AR14,"SB") -> 0 | AZ14: =SUM(AT14:AW14) -> 0 | BA14: =AT14*1+AU14*3+AV14*4+AW14*3 -> 0 | BB14: =IFERROR(INDEX('Month-1'!$F$3:$F$53,MATCH($B14,'Month-1'!$B$3:$B$53,0)),0) -> 0 | BC14: =BA14+BB14 -> 0 | BD14: =IFERROR(INDEX('Month-1'!$G$3:$G$53,MATCH($B14,'Month-1'!$B$3:$B$53,0)),0) + 1 -> 1 | BE14: =BC14/BD14 -> 0
G15: =IFERROR(IF(VLOOKUP($B15,'Month-1'!$B$3:$D$53,2,0)=0,"",VLOOKUP($B15,'Month-1'!$B$3:$D$53,2,0)),"") | H15: =IFERROR(IF(VLOOKUP($B15,'Month-1'!$B$3:$D$53,3,0)=0,"",VLOOKUP($B16,'Month-1'!$B$3:$D$53,3,0)),"") | AT15: =COUNTIFS(I15:AR15,"MO*",$I$2:$AR$2,"<5",$I$1:$AR$1,"<>PRE", $I$1:$AR$1,"<>Y") -> 0 | AU15: =COUNTIFS(I15:AR15,"MO*",$I$1:$AR$1,"PRE")+COUNTIFS(I15:AR15,"MO*",$I$2:$AR$2,"5",$I$1:$AR$1,"<>PRE",$I$1:$AR$1,"<>Y") -> 0 | AV15: =COUNTIFS(I15:AR15,"MO*",$I$1:$AR$1,"Y")+COUNTIFS(I15:AR15,"MO*",$I$2:$AR$2,"6",$I$1:$AR$1,"<>PRE",$I$1:$AR$1,"<>Y") -> 0 | AW15: =COUNTIFS(I15:AR15,"MO*", $I$2:$AR$2,"7",$I$1:$AR$1,"<>PRE", $I$1:$AR$1,"<>Y") -> 0 | AX15: =COUNTIF(I15:AR15,"WR*") -> 0 | AY15: =COUNTIF(I15:AR15,"SB") -> 0 | AZ15: =SUM(AT15:AW15) -> 0 | BA15: =AT15*1+AU15*3+AV15*4+AW15*3 -> 0 | BB15: =IFERROR(INDEX('Month-1'!$F$3:$F$53,MATCH($B15,'Month-1'!$B$3:$B$53,0)),0) -> 0 | BC15: =BA15+BB15 -> 0 | BD15: =IFERROR(INDEX('Month-1'!$G$3:$G$53,MATCH($B15,'Month-1'!$B$3:$B$53,0)),0) + 1 -> 1 | BE15: =BC15/BD15 -> 0
G16: =IFERROR(IF(VLOOKUP($B16,'Month-1'!$B$3:$D$53,2,0)=0,"",VLOOKUP($B16,'Month-1'!$B$3:$D$53,2,0)),"") | H16: =IFERROR(IF(VLOOKUP($B16,'Month-1'!$B$3:$D$53,3,0)=0,"",VLOOKUP($B17,'Month-1'!$B$3:$D$53,3,0)),"") | AT16: =COUNTIFS(I16:AR16,"MO*",$I$2:$AR$2,"<5",$I$1:$AR$1,"<>PRE", $I$1:$AR$1,"<>Y") -> 0 | AU16: =COUNTIFS(I16:AR16,"MO*",$I$1:$AR$1,"PRE")+COUNTIFS(I16:AR16,"MO*",$I$2:$AR$2,"5",$I$1:$AR$1,"<>PRE",$I$1:$AR$1,"<>Y") -> 0 | AV16: =COUNTIFS(I16:AR16,"MO*",$I$1:$AR$1,"Y")+COUNTIFS(I16:AR16,"MO*",$I$2:$AR$2,"6",$I$1:$AR$1,"<>PRE",$I$1:$AR$1,"<>Y") -> 0 | AW16: =COUNTIFS(I16:AR16,"MO*", $I$2:$AR$2,"7",$I$1:$AR$1,"<>PRE", $I$1:$AR$1,"<>Y") -> 0 | AX16: =COUNTIF(I16:AR16,"WR*") -> 0 | AY16: =COUNTIF(I16:AR16,"SB") -> 0 | AZ16: =SUM(AT16:AW16) -> 0 | BA16: =AT16*1+AU16*3+AV16*4+AW16*3 -> 0 | BB16: =IFERROR(INDEX('Month-1'!$F$3:$F$53,MATCH($B16,'Month-1'!$B$3:$B$53,0)),0) -> 0 | BC16: =BA16+BB16 -> 0 | BD16: =IFERROR(INDEX('Month-1'!$G$3:$G$53,MATCH($B16,'Month-1'!$B$3:$B$53,0)),0) + 1 -> 1 | BE16: =BC16/BD16 -> 0
G17: =IFERROR(IF(VLOOKUP($B17,'Month-1'!$B$3:$D$53,2,0)=0,"",VLOOKUP($B17,'Month-1'!$B$3:$D$53,2,0)),"") | H17: =IFERROR(IF(VLOOKUP($B17,'Month-1'!$B$3:$D$53,3,0)=0,"",VLOOKUP($B18,'Month-1'!$B$3:$D$53,3,0)),"") | AT17: =COUNTIFS(I17:AR17,"MO*",$I$2:$AR$2,"<5",$I$1:$AR$1,"<>PRE", $I$1:$AR$1,"<>Y") -> 0 | AU17: =COUNTIFS(I17:AR17,"MO*",$I$1:$AR$1,"PRE")+COUNTIFS(I17:AR17,"MO*",$I$2:$AR$2,"5",$I$1:$AR$1,"<>PRE",$I$1:$AR$1,"<>Y") -> 0 | AV17: =COUNTIFS(I17:AR17,"MO*",$I$1:$AR$1,"Y")+COUNTIFS(I17:AR17,"MO*",$I$2:$AR$2,"6",$I$1:$AR$1,"<>PRE",$I$1:$AR$1,"<>Y") -> 0 | AW17: =COUNTIFS(I17:AR17,"MO*", $I$2:$AR$2,"7",$I$1:$AR$1,"<>PRE", $I$1:$AR$1,"<>Y") -> 0 | AX17: =COUNTIF(I17:AR17,"WR*") -> 0 | AY17: =COUNTIF(I17:AR17,"SB") -> 0 | AZ17: =SUM(AT17:AW17) -> 0 | BA17: =AT17*1+AU17*3+AV17*4+AW17*3 -> 0 | BB17: =IFERROR(INDEX('Month-1'!$F$3:$F$53,MATCH($B17,'Month-1'!$B$3:$B$53,0)),0) -> 0 | BC17: =BA17+BB17 -> 0 | BD17: =IFERROR(INDEX('Month-1'!$G$3:$G$53,MATCH($B17,'Month-1'!$B$3:$B$53,0)),0) + 1 -> 1 | BE17: =BC17/BD17 -> 0
... G55: =IFERROR(IF(VLOOKUP($B55,'Month-1'!$B$3:$D$53,2,0)=0,"",VLOOKUP($B55,'Month-1'!$B$3:$D$53,2,0)),"") | H55: =IFERROR(IF(VLOOKUP($B55,'Month-1'!$B$3:$D$53,3,0)=0,"",VLOOKUP($B56,'Month-1'!$B$3:$D$53,3,0)),"") | AT55: =COUNTIFS(I55:AR55,"MO*",$I$2:$AR$2,"<5",$I$1:$AR$1,"<>PRE", $I$1:$AR$1,"<>Y") -> 0 | AU55: =COUNTIFS(I55:AR55,"MO*",$I$1:$AR$1,"PRE")+COUNTIFS(I55:AR55,"MO*",$I$2:$AR$2,"5",$I$1:$AR$1,"<>PRE",$I$1:$AR$1,"<>Y") -> 0 | AV55: =COUNTIFS(I55:AR55,"MO*",$I$1:$AR$1,"Y")+COUNTIFS(I55:AR55,"MO*",$I$2:$AR$2,"6",$I$1:$AR$1,"<>PRE",$I$1:$AR$1,"<>Y") -> 0 | AW55: =COUNTIFS(I55:AR55,"MO*", $I$2:$AR$2,"7",$I$1:$AR$1,"<>PRE", $I$1:$AR$1,"<>Y") -> 0 | AX55: =COUNTIF(I55:AR55,"WR*") -> 0 | AY55: =COUNTIF(I55:AR55,"SB") -> 0 | AZ55: =SUM(AT55:AW55) -> 0 | BA55: =AT55*1+AU55*3+AV55*4+AW55*3 -> 0 | BB55: =IFERROR(INDEX('Month-1'!$F$3:$F$53,MATCH($B55,'Month-1'!$B$3:$B$53,0)),0) -> 0 | BC55: =BA55+BB55 -> 0 | BD55: =IFERROR(INDEX('Month-1'!$G$3:$G$53,MATCH($B55,'Month-1'!$B$3:$B$53,0)),0) + 1 -> 1 | BE55: =BC55/BD55 -> 0
E57: MO1 | I57: =COUNTIFS(I$6:I$55,$E57) -> 0 | J57: =COUNTIFS(J$6:J$55,$E57) -> 0 | K57: =COUNTIFS(K$6:K$55,$E57) -> 0 | L57: =COUNTIFS(L$6:L$55,$E57) -> 0 | M57: =COUNTIFS(M$6:M$55,$E57) -> 0 | N57: =COUNTIFS(N$6:N$55,$E57) -> 0 | O57: =COUNTIFS(O$6:O$55,$E57) -> 0 | P57: =COUNTIFS(P$6:P$55,$E57) -> 0 | ... AR57: =COUNTIFS(AR$6:AR$55,$E57) -> 0
E58: MO2 | I58: =COUNTIFS(I$6:I$55,$E58) -> 0 | J58: =COUNTIFS(J$6:J$55,$E58) -> 0 | K58: =COUNTIFS(K$6:K$55,$E58) -> 0 | L58: =COUNTIFS(L$6:L$55,$E58) -> 0 | M58: =COUNTIFS(M$6:M$55,$E58) -> 0 | N58: =COUNTIFS(N$6:N$55,$E58) -> 0 | O58: =COUNTIFS(O$6:O$55,$E58) -> 0 | P58: =COUNTIFS(P$6:P$55,$E58) -> 0 | ... AR58: =COUNTIFS(AR$6:AR$55,$E58) -> 0
E59: MO3 | I59: =COUNTIFS(I$6:I$55,$E59) -> 0 | J59: =COUNTIFS(J$6:J$55,$E59) -> 0 | K59: =COUNTIFS(K$6:K$55,$E59) -> 0 | L59: =COUNTIFS(L$6:L$55,$E59) -> 0 | M59: =COUNTIFS(M$6:M$55,$E59) -> 0 | N59: =COUNTIFS(N$6:N$55,$E59) -> 0 | O59: =COUNTIFS(O$6:O$55,$E59) -> 0 | P59: =COUNTIFS(P$6:P$55,$E59) -> 0 | ... AR59: =COUNTIFS(AR$6:AR$55,$E59) -> 0
E60: MO4 | I60: =COUNTIFS(I$6:I$55,$E60) -> 0 | J60: =COUNTIFS(J$6:J$55,$E60) -> 0 | K60: =COUNTIFS(K$6:K$55,$E60) -> 0 | L60: =COUNTIFS(L$6:L$55,$E60) -> 0 | M60: =COUNTIFS(M$6:M$55,$E60) -> 0 | N60: =COUNTIFS(N$6:N$55,$E60) -> 0 | O60: =COUNTIFS(O$6:O$55,$E60) -> 0 | P60: =COUNTIFS(P$6:P$55,$E60) -> 0 | ... AR60: =COUNTIFS(AR$6:AR$55,$E60) -> 0
E61: MO5 | I61: =COUNTIFS(I$6:I$55,$E61) -> 0 | J61: =COUNTIFS(J$6:J$55,$E61) -> 0 | K61: =COUNTIFS(K$6:K$55,$E61) -> 0 | L61: =COUNTIFS(L$6:L$55,$E61) -> 0 | M61: =COUNTIFS(M$6:M$55,$E61) -> 0 | N61: =COUNTIFS(N$6:N$55,$E61) -> 0 | O61: =COUNTIFS(O$6:O$55,$E61) -> 0 | P61: =COUNTIFS(P$6:P$55,$E61) -> 0 | ... AR61: =COUNTIFS(AR$6:AR$55,$E61) -> 0
E62: MO6 | I62: =COUNTIFS(I$6:I$55,$E62) -> 0 | J62: =COUNTIFS(J$6:J$55,$E62) -> 0 | K62: =COUNTIFS(K$6:K$55,$E62) -> 0 | L62: =COUNTIFS(L$6:L$55,$E62) -> 0 | M62: =COUNTIFS(M$6:M$55,$E62) -> 0 | N62: =COUNTIFS(N$6:N$55,$E62) -> 0 | O62: =COUNTIFS(O$6:O$55,$E62) -> 0 | P62: =COUNTIFS(P$6:P$55,$E62) -> 0 | ... AR62: =COUNTIFS(AR$6:AR$55,$E62) -> 0
E63: WR | I63: =COUNTIFS(I$6:I$55,"WR*") -> 0 | J63: =COUNTIFS(J$6:J$55,"WR*") -> 0 | K63: =COUNTIFS(K$6:K$55,"WR*") -> 0 | L63: =COUNTIFS(L$6:L$55,"WR*") -> 0 | M63: =COUNTIFS(M$6:M$55,"WR*") -> 0 | N63: =COUNTIFS(N$6:N$55,"WR*") -> 0 | O63: =COUNTIFS(O$6:O$55,"WR*") -> 0 | P63: =COUNTIFS(P$6:P$55,"WR*") -> 0 | ... AR63: =COUNTIFS(AR$6:AR$55,"WR*") -> 0
E64: SB | I64: =COUNTIFS(I$6:I$55,"SB") -> 0 | J64: =COUNTIFS(J$6:J$55,"SB") -> 0 | K64: =COUNTIFS(K$6:K$55,"SB") -> 0 | L64: =COUNTIFS(L$6:L$55,"SB") -> 0 | M64: =COUNTIFS(M$6:M$55,"SB") -> 0 | N64: =COUNTIFS(N$6:N$55,"SB") -> 0 | O64: =COUNTIFS(O$6:O$55,"SB") -> 0 | P64: =COUNTIFS(P$6:P$55,"SB") -> 0 | ... AR64: =COUNTIFS(AR$6:AR$55,"SB") -> 0
B66: Legend
B67: REQUEST | D67: Call request
B68: BLOCK | D68: Call block
B69: LEAVE | D69: Leave or valid autoblock
B70: SUBSPEC | D70: Subspec limitation
B71: COURSE | D71: This day is blocked for course (course may be day itself or day of)
B72: RECENTCALL | D72: Blocked due to recent call
B73: WR | D73: Weekend Rounder
B74: SB | D74: Standby
B75: TAG1/2/3 | D75: Tag to MO1/2/3
B78: Call coverage
B79: Call | D79: Assign to Team (if possible) | E79: Coverage
B80: MO1 | D80: A / E | E80: 31/51/65 + 55 (weekdays)
B81: MO2 | D81: B | E81: 46/56/ 85
B82: MO3 | D82: C / D | E82: 41/66 / 44 + 86 (weekdays)
...

Sheet Month-1
B1: Month-1
B2: Name | C2: =Month!I5-2 -> 46117 | D2: =Month!I5-1 -> 46118 | E2: Total # of calls | F2: Total call points | G2: Total months

Sheet Infopedia
A1: DATE/DAY | C1: MEDICAL OFFICERS
C2: MO1 | D2: MO2 | E2: MO3 | F2: MO4 | G2: MO5 | H2: MO6 | I2: WR1 | J2: WR2 | K2: WR3 | L2: SB
C3: (31/51/65 + 55 Mon - Fri) | D3: (46/56/85) | E3: (41/44/66 + 86 Mon - Fri) | F3: (62/75/76) | G3: (55/86 Sat-Sun) | H3: (CICU) | I3: (Weekend Rounder) | J3: (Weekend Rounder) | K3: (Weekend Rounder) | L3: (Standby)
A4: =Month!I5 -> 46119 | B4: =TEXT(WEEKDAY(A4), "dddd") -> Tuesday | C4: =IFERROR(INDEX(Month!$B$6:$B$55,MATCH(C$2,INDEX(Month!$I$6:$AR$55,0,MATCH($A4,Month!$I$5:$AR$5,0)),0)),"") | D4: =IFERROR(INDEX(Month!$B$6:$B$55,MATCH(D$2,INDEX(Month!$I$6:$AR$55,0,MATCH($A4,Month!$I$5:$AR$5,0)),0)),"") | E4: =IFERROR(INDEX(Month!$B$6:$B$55,MATCH(E$2,INDEX(Month!$I$6:$AR$55,0,MATCH($A4,Month!$I$5:$AR$5,0)),0)),"") | F4: =IFERROR(INDEX(Month!$B$6:$B$55,MATCH(F$2,INDEX(Month!$I$6:$AR$55,0,MATCH($A4,Month!$I$5:$AR$5,0)),0)),"") | G4: =IFERROR(INDEX(Month!$B$6:$B$55,MATCH(G$2,INDEX(Month!$I$6:$AR$55,0,MATCH($A4,Month!$I$5:$AR$5,0)),0)),"") | H4: =IFERROR(INDEX(Month!$B$6:$B$55,MATCH(H$2,INDEX(Month!$I$6:$AR$55,0,MATCH($A4,Month!$I$5:$AR$5,0)),0)),"") | I4: =IFERROR(INDEX(Month!$B$6:$B$55,MATCH(I$2,INDEX(Month!$I$6:$AR$55,0,MATCH($A4,Month!$I$5:$AR$5,0)),0)),"") | J4: =IFERROR(INDEX(Month!$B$6:$B$55,MATCH(J$2,INDEX(Month!$I$6:$AR$55,0,MATCH($A4,Month!$I$5:$AR$5,0)),0)),"") | ... L4: =IFERROR(INDEX(Month!$B$6:$B$55,MATCH(L$2,INDEX(Month!$I$6:$AR$55,0,MATCH($A4,Month!$I$5:$AR$5,0)),0)),"")
A5: =A4+1 -> 46120 | B5: =TEXT(WEEKDAY(A5), "dddd") -> Wednesday | C5: =IFERROR(INDEX(Month!$B$6:$B$55,MATCH(C$2,INDEX(Month!$I$6:$AR$55,0,MATCH($A5,Month!$I$5:$AR$5,0)),0)),"") | D5: =IFERROR(INDEX(Month!$B$6:$B$55,MATCH(D$2,INDEX(Month!$I$6:$AR$55,0,MATCH($A5,Month!$I$5:$AR$5,0)),0)),"") | E5: =IFERROR(INDEX(Month!$B$6:$B$55,MATCH(E$2,INDEX(Month!$I$6:$AR$55,0,MATCH($A5,Month!$I$5:$AR$5,0)),0)),"") | F5: =IFERROR(INDEX(Month!$B$6:$B$55,MATCH(F$2,INDEX(Month!$I$6:$AR$55,0,MATCH($A5,Month!$I$5:$AR$5,0)),0)),"") | G5: =IFERROR(INDEX(Month!$B$6:$B$55,MATCH(G$2,INDEX(Month!$I$6:$AR$55,0,MATCH($A5,Month!$I$5:$AR$5,0)),0)),"") | H5: =IFERROR(INDEX(Month!$B$6:$B$55,MATCH(H$2,INDEX(Month!$I$6:$AR$55,0,MATCH($A5,Month!$I$5:$AR$5,0)),0)),"") | I5: =IFERROR(INDEX(Month!$B$6:$B$55,MATCH(I$2,INDEX(Month!$I$6:$AR$55,0,MATCH($A5,Month!$I$5:$AR$5,0)),0)),"") | J5: =IFERROR(INDEX(Month!$B$6:$B$55,MATCH(J$2,INDEX(Month!$I$6:$AR$55,0,MATCH($A5,Month!$I$5:$AR$5,0)),0)),"") | ... L5: =IFERROR(INDEX(Month!$B$6:$B$55,MATCH(L$2,INDEX(Month!$I$6:$AR$55,0,MATCH($A5,Month!$I$5:$AR$5,0)),0)),"")
A6: =A5+1 -> 46121 | B6: =TEXT(WEEKDAY(A6), "dddd") -> Thursday | C6: =IFERROR(INDEX(Month!$B$6:$B$55,MATCH(C$2,INDEX(Month!$I$6:$AR$55,0,MATCH($A6,Month!$I$5:$AR$5,0)),0)),"") | D6: =IFERROR(INDEX(Month!$B$6:$B$55,MATCH(D$2,INDEX(Month!$I$6:$AR$55,0,MATCH($A6,Month!$I$5:$AR$5,0)),0)),"") | E6: =IFERROR(INDEX(Month!$B$6:$B$55,MATCH(E$2,INDEX(Month!$I$6:$AR$55,0,MATCH($A6,Month!$I$5:$AR$5,0)),0)),"") | F6: =IFERROR(INDEX(Month!$B$6:$B$55,MATCH(F$2,INDEX(Month!$I$6:$AR$55,0,MATCH($A6,Month!$I$5:$AR$5,0)),0)),"") | G6: =IFERROR(INDEX(Month!$B$6:$B$55,MATCH(G$2,INDEX(Month!$I$6:$AR$55,0,MATCH($A6,Month!$I$5:$AR$5,0)),0)),"") | H6: =IFERROR(INDEX(Month!$B$6:$B$55,MATCH(H$2,INDEX(Month!$I$6:$AR$55,0,MATCH($A6,Month!$I$5:$AR$5,0)),0)),"") | I6: =IFERROR(INDEX(Month!$B$6:$B$55,MATCH(I$2,INDEX(Month!$I$6:$AR$55,0,MATCH($A6,Month!$I$5:$AR$5,0)),0)),"") | J6: =IFERROR(INDEX(Month!$B$6:$B$55,MATCH(J$2,INDEX(Month!$I$6:$AR$55,0,MATCH($A6,Month!$I$5:$AR$5,0)),0)),"") | ... L6: =IFERROR(INDEX(Month!$B$6:$B$55,MATCH(L$2,INDEX(Month!$I$6:$AR$55,0,MATCH($A6,Month!$I$5:$AR$5,0)),0)),"")
A7: =A6+1 -> 46122 | B7: =TEXT(WEEKDAY(A7), "dddd") -> Friday | C7: =IFERROR(INDEX(Month!$B$6:$B$55,MATCH(C$2,INDEX(Month!$I$6:$AR$55,0,MATCH($A7,Month!$I$5:$AR$5,0)),0)),"") | D7: =IFERROR(INDEX(Month!$B$6:$B$55,MATCH(D$2,INDEX(Month!$I$6:$AR$55,0,MATCH($A7,Month!$I$5:$AR$5,0)),0)),"") | E7: =IFERROR(INDEX(Month!$B$6:$B$55,MATCH(E$2,INDEX(Month!$I$6:$AR$55,0,MATCH($A7,Month!$I$5:$AR$5,0)),0)),"") | F7: =IFERROR(INDEX(Month!$B$6:$B$55,MATCH(F$2,INDEX(Month!$I$6:$AR$55,0,MATCH($A7,Month!$I$5:$AR$5,0)),0)),"") | G7: =IFERROR(INDEX(Month!$B$6:$B$55,MATCH(G$2,INDEX(Month!$I$6:$AR$55,0,MATCH($A7,Month!$I$5:$AR$5,0)),0)),"") | H7: =IFERROR(INDEX(Month!$B$6:$B$55,MATCH(H$2,INDEX(Month!$I$6:$AR$55,0,MATCH($A7,Month!$I$5:$AR$5,0)),0)),"") | I7: =IFERROR(INDEX(Month!$B$6:$B$55,MATCH(I$2,INDEX(Month!$I$6:$AR$55,0,MATCH($A7,Month!$I$5:$AR$5,0)),0)),"") | J7: =IFERROR(INDEX(Month!$B$6:$B$55,MATCH(J$2,INDEX(Month!$I$6:$AR$55,0,MATCH($A7,Month!$I$5:$AR$5,0)),0)),"") | ... L7: =IFERROR(INDEX(Month!$B$6:$B$55,MATCH(L$2,INDEX(Month!$I$6:$AR$55,0,MATCH($A7,Month!$I$5:$AR$5,0)),0)),"")
A8: =A7+1 -> 46123 | B8: =TEXT(WEEKDAY(A8), "dddd") -> Saturday | C8: =IFERROR(INDEX(Month!$B$6:$B$55,MATCH(C$2,INDEX(Month!$I$6:$AR$55,0,MATCH($A8,Month!$I$5:$AR$5,0)),0)),"") | D8: =IFERROR(INDEX(Month!$B$6:$B$55,MATCH(D$2,INDEX(Month!$I$6:$AR$55,0,MATCH($A8,Month!$I$5:$AR$5,0)),0)),"") | E8: =IFERROR(INDEX(Month!$B$6:$B$55,MATCH(E$2,INDEX(Month!$I$6:$AR$55,0,MATCH($A8,Month!$I$5:$AR$5,0)),0)),"") | F8: =IFERROR(INDEX(Month!$B$6:$B$55,MATCH(F$2,INDEX(Month!$I$6:$AR$55,0,MATCH($A8,Month!$I$5:$AR$5,0)),0)),"") | G8: =IFERROR(INDEX(Month!$B$6:$B$55,MATCH(G$2,INDEX(Month!$I$6:$AR$55,0,MATCH($A8,Month!$I$5:$AR$5,0)),0)),"") | H8: =IFERROR(INDEX(Month!$B$6:$B$55,MATCH(H$2,INDEX(Month!$I$6:$AR$55,0,MATCH($A8,Month!$I$5:$AR$5,0)),0)),"") | I8: =IFERROR(INDEX(Month!$B$6:$B$55,MATCH(I$2,INDEX(Month!$I$6:$AR$55,0,MATCH($A8,Month!$I$5:$AR$5,0)),0)),"") | J8: =IFERROR(INDEX(Month!$B$6:$B$55,MATCH(J$2,INDEX(Month!$I$6:$AR$55,0,MATCH($A8,Month!$I$5:$AR$5,0)),0)),"") | ... L8: =IFERROR(INDEX(Month!$B$6:$B$55,MATCH(L$2,INDEX(Month!$I$6:$AR$55,0,MATCH($A8,Month!$I$5:$AR$5,0)),0)),"")
A9: =A8+1 -> 46124 | B9: =TEXT(WEEKDAY(A9), "dddd") -> Sunday | C9: =IFERROR(INDEX(Month!$B$6:$B$55,MATCH(C$2,INDEX(Month!$I$6:$AR$55,0,MATCH($A9,Month!$I$5:$AR$5,0)),0)),"") | D9: =IFERROR(INDEX(Month!$B$6:$B$55,MATCH(D$2,INDEX(Month!$I$6:$AR$55,0,MATCH($A9,Month!$I$5:$AR$5,0)),0)),"") | E9: =IFERROR(INDEX(Month!$B$6:$B$55,MATCH(E$2,INDEX(Month!$I$6:$AR$55,0,MATCH($A9,Month!$I$5:$AR$5,0)),0)),"") | F9: =IFERROR(INDEX(Month!$B$6:$B$55,MATCH(F$2,INDEX(Month!$I$6:$AR$55,0,MATCH($A9,Month!$I$5:$AR$5,0)),0)),"") | G9: =IFERROR(INDEX(Month!$B$6:$B$55,MATCH(G$2,INDEX(Month!$I$6:$AR$55,0,MATCH($A9,Month!$I$5:$AR$5,0)),0)),"") | H9: =IFERROR(INDEX(Month!$B$6:$B$55,MATCH(H$2,INDEX(Month!$I$6:$AR$55,0,MATCH($A9,Month!$I$5:$AR$5,0)),0)),"") | I9: =IFERROR(INDEX(Month!$B$6:$B$55,MATCH(I$2,INDEX(Month!$I$6:$AR$55,0,MATCH($A9,Month!$I$5:$AR$5,0)),0)),"") | J9: =IFERROR(INDEX(Month!$B$6:$B$55,MATCH(J$2,INDEX(Month!$I$6:$AR$55,0,MATCH($A9,Month!$I$5:$AR$5,0)),0)),"") | ... L9: =IFERROR(INDEX(Month!$B$6:$B$55,MATCH(L$2,INDEX(Month!$I$6:$AR$55,0,MATCH($A9,Month!$I$5:$AR$5,0)),0)),"")
A10: =A9+1 -> 46125 | B10: =TEXT(WEEKDAY(A10), "dddd") -> Monday | C10: =IFERROR(INDEX(Month!$B$6:$B$55,MATCH(C$2,INDEX(Month!$I$6:$AR$55,0,MATCH($A10,Month!$I$5:$AR$5,0)),0)),"") | D10: =IFERROR(INDEX(Month!$B$6:$B$55,MATCH(D$2,INDEX(Month!$I$6:$AR$55,0,MATCH($A10,Month!$I$5:$AR$5,0)),0)),"") | E10: =IFERROR(INDEX(Month!$B$6:$B$55,MATCH(E$2,INDEX(Month!$I$6:$AR$55,0,MATCH($A10,Month!$I$5:$AR$5,0)),0)),"") | F10: =IFERROR(INDEX(Month!$B$6:$B$55,MATCH(F$2,INDEX(Month!$I$6:$AR$55,0,MATCH($A10,Month!$I$5:$AR$5,0)),0)),"") | G10: =IFERROR(INDEX(Month!$B$6:$B$55,MATCH(G$2,INDEX(Month!$I$6:$AR$55,0,MATCH($A10,Month!$I$5:$AR$5,0)),0)),"") | H10: =IFERROR(INDEX(Month!$B$6:$B$55,MATCH(H$2,INDEX(Month!$I$6:$AR$55,0,MATCH($A10,Month!$I$5:$AR$5,0)),0)),"") | I10: =IFERROR(INDEX(Month!$B$6:$B$55,MATCH(I$2,INDEX(Month!$I$6:$AR$55,0,MATCH($A10,Month!$I$5:$AR$5,0)),0)),"") | J10: =IFERROR(INDEX(Month!$B$6:$B$55,MATCH(J$2,INDEX(Month!$I$6:$AR$55,0,MATCH($A10,Month!$I$5:$AR$5,0)),0)),"") | ... L10: =IFERROR(INDEX(Month!$B$6:$B$55,MATCH(L$2,INDEX(Month!$I$6:$AR$55,0,MATCH($A10,Month!$I$5:$AR$5,0)),0)),"")
A11: =A10+1 -> 46126 | B11: =TEXT(WEEKDAY(A11), "dddd") -> Tuesday | C11: =IFERROR(INDEX(Month!$B$6:$B$55,MATCH(C$2,INDEX(Month!$I$6:$AR$55,0,MATCH($A11,Month!$I$5:$AR$5,0)),0)),"") | D11: =IFERROR(INDEX(Month!$B$6:$B$55,MATCH(D$2,INDEX(Month!$I$6:$AR$55,0,MATCH($A11,Month!$I$5:$AR$5,0)),0)),"") | E11: =IFERROR(INDEX(Month!$B$6:$B$55,MATCH(E$2,INDEX(Month!$I$6:$AR$55,0,MATCH($A11,Month!$I$5:$AR$5,0)),0)),"") | F11: =IFERROR(INDEX(Month!$B$6:$B$55,MATCH(F$2,INDEX(Month!$I$6:$AR$55,0,MATCH($A11,Month!$I$5:$AR$5,0)),0)),"") | G11: =IFERROR(INDEX(Month!$B$6:$B$55,MATCH(G$2,INDEX(Month!$I$6:$AR$55,0,MATCH($A11,Month!$I$5:$AR$5,0)),0)),"") | H11: =IFERROR(INDEX(Month!$B$6:$B$55,MATCH(H$2,INDEX(Month!$I$6:$AR$55,0,MATCH($A11,Month!$I$5:$AR$5,0)),0)),"") | I11: =IFERROR(INDEX(Month!$B$6:$B$55,MATCH(I$2,INDEX(Month!$I$6:$AR$55,0,MATCH($A11,Month!$I$5:$AR$5,0)),0)),"") | J11: =IFERROR(INDEX(Month!$B$6:$B$55,MATCH(J$2,INDEX(Month!$I$6:$AR$55,0,MATCH($A11,Month!$I$5:$AR$5,0)),0)),"") | ... L11: =IFERROR(INDEX(Month!$B$6:$B$55,MATCH(L$2,INDEX(Month!$I$6:$AR$55,0,MATCH($A11,Month!$I$5:$AR$5,0)),0)),"")
A12: =A11+1 -> 46127 | B12: =TEXT(WEEKDAY(A12), "dddd") -> Wednesday | C12: =IFERROR(INDEX(Month!$B$6:$B$55,MATCH(C$2,INDEX(Month!$I$6:$AR$55,0,MATCH($A12,Month!$I$5:$AR$5,0)),0)),"") | D12: =IFERROR(INDEX(Month!$B$6:$B$55,MATCH(D$2,INDEX(Month!$I$6:$AR$55,0,MATCH($A12,Month!$I$5:$AR$5,0)),0)),"") | E12: =IFERROR(INDEX(Month!$B$6:$B$55,MATCH(E$2,INDEX(Month!$I$6:$AR$55,0,MATCH($A12,Month!$I$5:$AR$5,0)),0)),"") | F12: =IFERROR(INDEX(Month!$B$6:$B$55,MATCH(F$2,INDEX(Month!$I$6:$AR$55,0,MATCH($A12,Month!$I$5:$AR$5,0)),0)),"") | G12: =IFERROR(INDEX(Month!$B$6:$B$55,MATCH(G$2,INDEX(Month!$I$6:$AR$55,0,MATCH($A12,Month!$I$5:$AR$5,0)),0)),"") | H12: =IFERROR(INDEX(Month!$B$6:$B$55,MATCH(H$2,INDEX(Month!$I$6:$AR$55,0,MATCH($A12,Month!$I$5:$AR$5,0)),0)),"") | I12: =IFERROR(INDEX(Month!$B$6:$B$55,MATCH(I$2,INDEX(Month!$I$6:$AR$55,0,MATCH($A12,Month!$I$5:$AR$5,0)),0)),"") | J12: =IFERROR(INDEX(Month!$B$6:$B$55,MATCH(J$2,INDEX(Month!$I$6:$AR$55,0,MATCH($A12,Month!$I$5:$AR$5,0)),0)),"") | ... L12: =IFERROR(INDEX(Month!$B$6:$B$55,MATCH(L$2,INDEX(Month!$I$6:$AR$55,0,MATCH($A12,Month!$I$5:$AR$5,0)),0)),"")
A13: =A12+1 -> 46128 | B13: =TEXT(WEEKDAY(A13), "dddd") -> Thursday | C13: =IFERROR(INDEX(Month!$B$6:$B$55,MATCH(C$2,INDEX(Month!$I$6:$AR$55,0,MATCH($A13,Month!$I$5:$AR$5,0)),0)),"") | D13: =IFERROR(INDEX(Month!$B$6:$B$55,MATCH(D$2,INDEX(Month!$I$6:$AR$55,0,MATCH($A13,Month!$I$5:$AR$5,0)),0)),"") | E13: =IFERROR(INDEX(Month!$B$6:$B$55,MATCH(E$2,INDEX(Month!$I$6:$AR$55,0,MATCH($A13,Month!$I$5:$AR$5,0)),0)),"") | F13: =IFERROR(INDEX(Month!$B$6:$B$55,MATCH(F$2,INDEX(Month!$I$6:$AR$55,0,MATCH($A13,Month!$I$5:$AR$5,0)),0)),"") | G13: =IFERROR(INDEX(Month!$B$6:$B$55,MATCH(G$2,INDEX(Month!$I$6:$AR$55,0,MATCH($A13,Month!$I$5:$AR$5,0)),0)),"") | H13: =IFERROR(INDEX(Month!$B$6:$B$55,MATCH(H$2,INDEX(Month!$I$6:$AR$55,0,MATCH($A13,Month!$I$5:$AR$5,0)),0)),"") | I13: =IFERROR(INDEX(Month!$B$6:$B$55,MATCH(I$2,INDEX(Month!$I$6:$AR$55,0,MATCH($A13,Month!$I$5:$AR$5,0)),0)),"") | J13: =IFERROR(INDEX(Month!$B$6:$B$55,MATCH(J$2,INDEX(Month!$I$6:$AR$55,0,MATCH($A13,Month!$I$5:$AR$5,0)),0)),"") | ... L13: =IFERROR(INDEX(Month!$B$6:$B$55,MATCH(L$2,INDEX(Month!$I$6:$AR$55,0,MATCH($A13,Month!$I$5:$AR$5,0)),0)),"")
A14: =A13+1 -> 46129 | B14: =TEXT(WEEKDAY(A14), "dddd") -> Friday | C14: =IFERROR(INDEX(Month!$B$6:$B$55,MATCH(C$2,INDEX(Month!$I$6:$AR$55,0,MATCH($A14,Month!$I$5:$AR$5,0)),0)),"") | D14: =IFERROR(INDEX(Month!$B$6:$B$55,MATCH(D$2,INDEX(Month!$I$6:$AR$55,0,MATCH($A14,Month!$I$5:$AR$5,0)),0)),"") | E14: =IFERROR(INDEX(Month!$B$6:$B$55,MATCH(E$2,INDEX(Month!$I$6:$AR$55,0,MATCH($A14,Month!$I$5:$AR$5,0)),0)),"") | F14: =IFERROR(INDEX(Month!$B$6:$B$55,MATCH(F$2,INDEX(Month!$I$6:$AR$55,0,MATCH($A14,Month!$I$5:$AR$5,0)),0)),"") | G14: =IFERROR(INDEX(Month!$B$6:$B$55,MATCH(G$2,INDEX(Month!$I$6:$AR$55,0,MATCH($A14,Month!$I$5:$AR$5,0)),0)),"") | H14: =IFERROR(INDEX(Month!$B$6:$B$55,MATCH(H$2,INDEX(Month!$I$6:$AR$55,0,MATCH($A14,Month!$I$5:$AR$5,0)),0)),"") | I14: =IFERROR(INDEX(Month!$B$6:$B$55,MATCH(I$2,INDEX(Month!$I$6:$AR$55,0,MATCH($A14,Month!$I$5:$AR$5,0)),0)),"") | J14: =IFERROR(INDEX(Month!$B$6:$B$55,MATCH(J$2,INDEX(Month!$I$6:$AR$55,0,MATCH($A14,Month!$I$5:$AR$5,0)),0)),"") | ... L14: =IFERROR(INDEX(Month!$B$6:$B$55,MATCH(L$2,INDEX(Month!$I$6:$AR$55,0,MATCH($A14,Month!$I$5:$AR$5,0)),0)),"")
A15: =A14+1 -> 46130 | B15: =TEXT(WEEKDAY(A15), "dddd") -> Saturday | C15: =IFERROR(INDEX(Month!$B$6:$B$55,MATCH(C$2,INDEX(Month!$I$6:$AR$55,0,MATCH($A15,Month!$I$5:$AR$5,0)),0)),"") | D15: =IFERROR(INDEX(Month!$B$6:$B$55,MATCH(D$2,INDEX(Month!$I$6:$AR$55,0,MATCH($A15,Month!$I$5:$AR$5,0)),0)),"") | E15: =IFERROR(INDEX(Month!$B$6:$B$55,MATCH(E$2,INDEX(Month!$I$6:$AR$55,0,MATCH($A15,Month!$I$5:$AR$5,0)),0)),"") | F15: =IFERROR(INDEX(Month!$B$6:$B$55,MATCH(F$2,INDEX(Month!$I$6:$AR$55,0,MATCH($A15,Month!$I$5:$AR$5,0)),0)),"") | G15: =IFERROR(INDEX(Month!$B$6:$B$55,MATCH(G$2,INDEX(Month!$I$6:$AR$55,0,MATCH($A15,Month!$I$5:$AR$5,0)),0)),"") | H15: =IFERROR(INDEX(Month!$B$6:$B$55,MATCH(H$2,INDEX(Month!$I$6:$AR$55,0,MATCH($A15,Month!$I$5:$AR$5,0)),0)),"") | I15: =IFERROR(INDEX(Month!$B$6:$B$55,MATCH(I$2,INDEX(Month!$I$6:$AR$55,0,MATCH($A15,Month!$I$5:$AR$5,0)),0)),"") | J15: =IFERROR(INDEX(Month!$B$6:$B$55,MATCH(J$2,INDEX(Month!$I$6:$AR$55,0,MATCH($A15,Month!$I$5:$AR$5,0)),0)),"") | ... L15: =IFERROR(INDEX(Month!$B$6:$B$55,MATCH(L$2,INDEX(Month!$I$6:$AR$55,0,MATCH($A15,Month!$I$5:$AR$5,0)),0)),"")
A16: =A15+1 -> 46131 | B16: =TEXT(WEEKDAY(A16), "dddd") -> Sunday | C16: =IFERROR(INDEX(Month!$B$6:$B$55,MATCH(C$2,INDEX(Month!$I$6:$AR$55,0,MATCH($A16,Month!$I$5:$AR$5,0)),0)),"") | D16: =IFERROR(INDEX(Month!$B$6:$B$55,MATCH(D$2,INDEX(Month!$I$6:$AR$55,0,MATCH($A16,Month!$I$5:$AR$5,0)),0)),"") | E16: =IFERROR(INDEX(Month!$B$6:$B$55,MATCH(E$2,INDEX(Month!$I$6:$AR$55,0,MATCH($A16,Month!$I$5:$AR$5,0)),0)),"") | F16: =IFERROR(INDEX(Month!$B$6:$B$55,MATCH(F$2,INDEX(Month!$I$6:$AR$55,0,MATCH($A16,Month!$I$5:$AR$5,0)),0)),"") | G16: =IFERROR(INDEX(Month!$B$6:$B$55,MATCH(G$2,INDEX(Month!$I$6:$AR$55,0,MATCH($A16,Month!$I$5:$AR$5,0)),0)),"") | H16: =IFERROR(INDEX(Month!$B$6:$B$55,MATCH(H$2,INDEX(Month!$I$6:$AR$55,0,MATCH($A16,Month!$I$5:$AR$5,0)),0)),"") | I16: =IFERROR(INDEX(Month!$B$6:$B$55,MATCH(I$2,INDEX(Month!$I$6:$AR$55,0,MATCH($A16,Month!$I$5:$AR$5,0)),0)),"") | J16: =IFERROR(INDEX(Month!$B$6:$B$55,MATCH(J$2,INDEX(Month!$I$6:$AR$55,0,MATCH($A16,Month!$I$5:$AR$5,0)),0)),"") | ... L16: =IFERROR(INDEX(Month!$B$6:$B$55,MATCH(L$2,INDEX(Month!$I$6:$AR$55,0,MATCH($A16,Month!$I$5:$AR$5,0)),0)),"")
... A43: =A42+1 -> 46158 | B43: =TEXT(WEEKDAY(A43), "dddd") -> Saturday | C43: =IFERROR(INDEX(Month!$B$6:$B$55,MATCH(C$2,INDEX(Month!$I$6:$AR$55,0,MATCH($A43,Month!$I$5:$AR$5,0)),0)),"") | D43: =IFERROR(INDEX(Month!$B$6:$B$55,MATCH(D$2,INDEX(Month!$I$6:$AR$55,0,MATCH($A43,Month!$I$5:$AR$5,0)),0)),"") | E43: =IFERROR(INDEX(Month!$B$6:$B$55,MATCH(E$2,INDEX(Month!$I$6:$AR$55,0,MATCH($A43,Month!$I$5:$AR$5,0)),0)),"") | F43: =IFERROR(INDEX(Month!$B$6:$B$55,MATCH(F$2,INDEX(Month!$I$6:$AR$55,0,MATCH($A43,Month!$I$5:$AR$5,0)),0)),"") | G43: =IFERROR(INDEX(Month!$B$6:$B$55,MATCH(G$2,INDEX(Month!$I$6:$AR$55,0,MATCH($A43,Month!$I$5:$AR$5,0)),0)),"") | H43: =IFERROR(INDEX(Month!$B$6:$B$55,MATCH(H$2,INDEX(Month!$I$6:$AR$55,0,MATCH($A43,Month!$I$5:$AR$5,0)),0)),"") | I43: =IFERROR(INDEX(Month!$B$6:$B$55,MATCH(I$2,INDEX(Month!$I$6:$AR$55,0,MATCH($A43,Month!$I$5:$AR$5,0)),0)),"") | J43: =IFERROR(INDEX(Month!$B$6:$B$55,MATCH(J$2,INDEX(Month!$I$6:$AR$55,0,MATCH($A43,Month!$I$5:$AR$5,0)),0)),"") | ... L43: =IFERROR(INDEX(Month!$B$6:$B$55,MATCH(L$2,INDEX(Month!$I$6:$AR$55,0,MATCH($A43,Month!$I$5:$AR$5,0)),0)),"")

Sheet Jan 26
D2: 1 | E2: =D2+1 -> 2 | F2: =E2+1 -> 3 | G2: =F2+1 -> 4 | H2: =G2+1 -> 5 | I2: =H2+1 -> 6 | J2: =I2+1 -> 7 | K2: =J2+1 -> 8 | L2: =K2+1 -> 9 | ... BC2: =BB2+1 -> 52
D3: 46023 | E3: PH? | F3: N | G3: N | H3: N | I3: N | J3: N | K3: N | L3: N | M3: N | N3: N | O3: N | P3: N | Q3: N | R3: N | S3: N | T3: N | U3: N | V3: N | W3: N | X3: N | Y3: N | Z3: N | AA3: N | AB3: N | AC3: N | AD3: N | AE3: N | AF3: N | AG3: N | AH3: N | AJ3: Imported
F4: Last cycle | H4: New cycle | AJ4: Last cycle | AN4: This cycle
B5: 1 | F5: 46027 | G5: =F5+1 -> 46028 | H5: =G5+1 -> 46029 | I5: =H5+1 -> 46030 | J5: =I5+1 -> 46031 | K5: =J5+1 -> 46032 | L5: =K5+1 -> 46033 | M5: =L5+1 -> 46034 | N5: =M5+1 -> 46035 | ... AH5: =AG5+1 -> 46055 | AJ5: Culmulative | AN5: Calls | AT5: Calculated | AY5: Culmulative
B6: =B5+1 -> 2 | F6: =WEEKDAY(F5,2) -> 1 | G6: =WEEKDAY(G5,2) -> 2 | H6: =WEEKDAY(H5,2) -> 3 | I6: =WEEKDAY(I5,2) -> 4 | J6: =WEEKDAY(J5,2) -> 5 | K6: =WEEKDAY(K5,2) -> 6 | L6: =WEEKDAY(L5,2) -> 7 | M6: =WEEKDAY(M5,2) -> 1 | ... AC6: =WEEKDAY(AC5,2) -> 3 | AD6: 4 | AE6: 5 | AF6: =WEEKDAY(AF5,2) -> 6 | AG6: =WEEKDAY(AG5,2) -> 7 | AH6: =WEEKDAY(AH5,2) -> 1
B7: =B6+1 -> 3 | C7: S/N | D7: Name | E7: Ward | F7: =VLOOKUP(WEEKDAY(F5,2),Index!$B$2:$C$8,2,0) -> Monday | G7: =VLOOKUP(WEEKDAY(G5,2),Index!$B$2:$C$8,2,0) -> Tuesday | H7: =VLOOKUP(WEEKDAY(H5,2),Index!$B$2:$C$8,2,0) -> Wednesday | I7: =VLOOKUP(WEEKDAY(I5,2),Index!$B$2:$C$8,2,0) -> Thursday | J7: =VLOOKUP(WEEKDAY(J5,2),Index!$B$2:$C$8,2,0) -> Friday | K7: =VLOOKUP(WEEKDAY(K5,2),Index!$B$2:$C$8,2,0) -> Saturday | L7: =VLOOKUP(WEEKDAY(L5,2),Index!$B$2:$C$8,2,0) -> Sunday | M7: =VLOOKUP(WEEKDAY(M5,2),Index!$B$2:$C$8,2,0) -> Monday | ... AH7: =VLOOKUP(WEEKDAY(AH5,2),Index!$B$2:$C$8,2,0) -> Monday | AJ7: # of calls | AK7: Call points | AL7: Weekends off | AM7: Weekend rounds | AN7: Weekday | AO7: Friday/Pre-PH | AP7: Satuday/PH | AQ7: Sunday | AR7: HO6 | AS7: SB | AT7: # of calls | AU7: Call points | AV7: Weekends off | AW7: Weekend rounds | AX7: Average points per call | AY7: # of calls | AZ7: Call points | BA7: Weekends off | BB7: Weekend rounds | BC7: Average points per call
B8: =B7+1 -> 4 | C8: 1 | D8: Ashley Chen | E8: 31 | F8: =IFERROR(IF(VLOOKUP($D8,'Dec 25'!$D$8:$AQ$43,39,0)=0,"",VLOOKUP($D8,'Dec 25'!$D$8:$AQ$43,39,0)),"") | G8: =IFERROR(IF(VLOOKUP($D8,'Dec 25'!$D$8:$AQ$43,40,0)=0,"",VLOOKUP($D8,'Dec 25'!$D$8:$AQ$43,40,0)),"") | N8: SB | R8: HO1 | Y8: WR1 | AA8: HO1 | AE8: HO1 | AJ8: =IFERROR(VLOOKUP($D8,'Dec 25'!$D$8:$BL$43,57,0),0) -> 0 | AK8: =IFERROR(VLOOKUP($D8,'Dec 25'!$D$8:$BL$43,58,0),0) -> 0 | AL8: =IFERROR(VLOOKUP($D8,'Dec 25'!$D$8:$BL$43,59,0),0) -> 0 | AM8: =IFERROR(VLOOKUP($D8,'Dec 25'!$D$8:$BL$43,60,0),0) -> 0 | AN8: =COUNTIFS(H8:AH8,"HO*",$H$6:$AH$6,"<5") -> 1 | AO8: =COUNTIFS(H8:AH8,"HO*",$H$6:$AH$6,"5") -> 1 | AP8: =COUNTIFS(H8:AH8,"HO*",$H$6:$AH$6,"6")-COUNTIFS(H8:AH8,"HO6",$H$6:$AH$6,"6") -> 1 | AQ8: =COUNTIFS(H8:AH8,"HO*",$H$6:$AH$6,"7")-COUNTIFS(H8:AH8,"HO6",$H$6:$AH$6,"7") -> 0 | AR8: =COUNTIF(H8:AH8,"HO6") -> 0 | AS8: =COUNTIF(H8:AH8,"SB") -> 1 | AT8: =SUM(AN8:AQ8)+AR8*0.5 -> 3 | AU8: =AN8*1+AO8*1.5+AP8*2.5+AQ8*2+AR8*0.5 -> 5 | AV8: =COUNTIFS(H8:AH8,"",$H$6:$AH$6,">5")+COUNTIFS(H8:AH8,"X",$H$6:$AH$6,">5") -> 6 | AW8: =COUNTIF(H8:AH8,"WR*") -> 1 | AX8: =AU8/AT8 -> 1.6666667 | AY8: =AT8+AJ8 -> 3 | AZ8: =AU8+AK8 -> 5 | BA8: =AV8+AL8 -> 6 | BB8: =AW8+AM8 -> 1 | BC8: =AZ8/AY8 -> 1.6666667
B9: =B8+1 -> 5 | C9: =C8+1 -> 2 | D9: Lavanya Rawat | E9: 31 | F9: =IFERROR(IF(VLOOKUP($D9,'Dec 25'!$D$8:$AQ$43,39,0)=0,"",VLOOKUP($D9,'Dec 25'!$D$8:$AQ$43,39,0)),"") | G9: =IFERROR(IF(VLOOKUP($D9,'Dec 25'!$D$8:$AQ$43,40,0)=0,"",VLOOKUP($D9,'Dec 25'!$D$8:$AQ$43,40,0)),"") | L9: WR1 | S9: HO1 | Y9: SB | AC9: HO1 | AG9: HO1 | AJ9: =IFERROR(VLOOKUP($D9,'Dec 25'!$D$8:$BL$43,57,0),0) -> 0 | AK9: =IFERROR(VLOOKUP($D9,'Dec 25'!$D$8:$BL$43,58,0),0) -> 0 | AL9: =IFERROR(VLOOKUP($D9,'Dec 25'!$D$8:$BL$43,59,0),0) -> 0 | AM9: =IFERROR(VLOOKUP($D9,'Dec 25'!$D$8:$BL$43,60,0),0) -> 0 | AN9: =COUNTIFS(H9:AH9,"HO*",$H$6:$AH$6,"<5") -> 1 | AO9: =COUNTIFS(H9:AH9,"HO*",$H$6:$AH$6,"5") -> 0 | AP9: =COUNTIFS(H9:AH9,"HO*",$H$6:$AH$6,"6")-COUNTIFS(H9:AH9,"HO6",$H$6:$AH$6,"6") -> 0 | AQ9: =COUNTIFS(H9:AH9,"HO*",$H$6:$AH$6,"7")-COUNTIFS(H9:AH9,"HO6",$H$6:$AH$6,"7") -> 2 | AR9: =COUNTIF(H9:AH9,"HO6") -> 0 | AS9: =COUNTIF(H9:AH9,"SB") -> 1 | AT9: =SUM(AN9:AQ9)+AR9*0.5 -> 3 | AU9: =AN9*1+AO9*1.5+AP9*2.5+AQ9*2+AR9*0.5 -> 5 | AV9: =COUNTIFS(H9:AH9,"",$H$6:$AH$6,">5")+COUNTIFS(H9:AH9,"X",$H$6:$AH$6,">5") -> 4 | AW9: =COUNTIF(H9:AH9,"WR*") -> 1 | AX9: =AU9/AT9 -> 1.6666667 | AY9: =AT9+AJ9 -> 3 | AZ9: =AU9+AK9 -> 5 | BA9: =AV9+AL9 -> 4 | BB9: =AW9+AM9 -> 1 | BC9: =AZ9/AY9 -> 1.6666667
B10: =B9+1 -> 6 | C10: =C9+1 -> 3 | D10: Shaiful Aslam | E10: 31 | F10: =IFERROR(IF(VLOOKUP($D10,'Dec 25'!$D$8:$AQ$43,39,0)=0,"",VLOOKUP($D10,'Dec 25'!$D$8:$AQ$43,39,0)),"") | G10: =IFERROR(IF(VLOOKUP($D10,'Dec 25'!$D$8:$AQ$43,40,0)=0,"",VLOOKUP($D10,'Dec 25'!$D$8:$AQ$43,40,0)),"") | K10: HO1 | W10: SB | Z10: WR1 | AB10: HO1 | AE10: HO2 | AG10: PRE-LEAVE | AH10: LEAVE | AJ10: =IFERROR(VLOOKUP($D10,'Dec 25'!$D$8:$BL$43,57,0),0) -> 0 | AK10: =IFERROR(VLOOKUP($D10,'Dec 25'!$D$8:$BL$43,58,0),0) -> 0 | AL10: =IFERROR(VLOOKUP($D10,'Dec 25'!$D$8:$BL$43,59,0),0) -> 0 | AM10: =IFERROR(VLOOKUP($D10,'Dec 25'!$D$8:$BL$43,60,0),0) -> 0 | AN10: =COUNTIFS(H10:AH10,"HO*",$H$6:$AH$6,"<5") -> 1 | AO10: =COUNTIFS(H10:AH10,"HO*",$H$6:$AH$6,"5") -> 1 | AP10: =COUNTIFS(H10:AH10,"HO*",$H$6:$AH$6,"6")-COUNTIFS(H10:AH10,"HO6",$H$6:$AH$6,"6") -> 1 | AQ10: =COUNTIFS(H10:AH10,"HO*",$H$6:$AH$6,"7")-COUNTIFS(H10:AH10,"HO6",$H$6:$AH$6,"7") -> 0 | AR10: =COUNTIF(H10:AH10,"HO6") -> 0 | AS10: =COUNTIF(H10:AH10,"SB") -> 1 | AT10: =SUM(AN10:AQ10)+AR10*0.5 -> 3 | AU10: =AN10*1+AO10*1.5+AP10*2.5+AQ10*2+AR10*0.5 -> 5 | AV10: =COUNTIFS(H10:AH10,"",$H$6:$AH$6,">5")+COUNTIFS(H10:AH10,"X",$H$6:$AH$6,">5") -> 5 | AW10: =COUNTIF(H10:AH10,"WR*") -> 1 | AX10: =AU10/AT10 -> 1.6666667 | AY10: =AT10+AJ10 -> 3 | AZ10: =AU10+AK10 -> 5 | BA10: =AV10+AL10 -> 5 | BB10: =AW10+AM10 -> 1 | BC10: =AZ10/AY10 -> 1.6666667
B11: =B10+1 -> 7 | C11: =C10+1 -> 4 | D11: Lee Yixuan | E11: 55 | F11: =IFERROR(IF(VLOOKUP($D11,'Dec 25'!$D$8:$AQ$43,39,0)=0,"",VLOOKUP($D11,'Dec 25'!$D$8:$AQ$43,39,0)),"") | G11: =IFERROR(IF(VLOOKUP($D11,'Dec 25'!$D$8:$AQ$43,40,0)=0,"",VLOOKUP($D11,'Dec 25'!$D$8:$AQ$43,40,0)),"") -> HO4 | H11: PRE-LEAVE | I11: LEAVE | J11: HO5 | Q11: SB | T11: HO5 | U11: PRE-LEAVE | V11: LEAVE | Z11: HO5 | AH11: HO3 | AJ11: =IFERROR(VLOOKUP($D11,'Dec 25'!$D$8:$BL$43,57,0),0) -> 9.5 | AK11: =IFERROR(VLOOKUP($D11,'Dec 25'!$D$8:$BL$43,58,0),0) -> 14 | AL11: =IFERROR(VLOOKUP($D11,'Dec 25'!$D$8:$BL$43,59,0),0) -> 19 | AM11: =IFERROR(VLOOKUP($D11,'Dec 25'!$D$8:$BL$43,60,0),0) -> 3 | AN11: =COUNTIFS(H11:AH11,"HO*",$H$6:$AH$6,"<5") -> 2 | AO11: =COUNTIFS(H11:AH11,"HO*",$H$6:$AH$6,"5") -> 1 | AP11: =COUNTIFS(H11:AH11,"HO*",$H$6:$AH$6,"6")-COUNTIFS(H11:AH11,"HO6",$H$6:$AH$6,"6") -> 0 | AQ11: =COUNTIFS(H11:AH11,"HO*",$H$6:$AH$6,"7")-COUNTIFS(H11:AH11,"HO6",$H$6:$AH$6,"7") -> 1 | AR11: =COUNTIF(H11:AH11,"HO6") -> 0 | AS11: =COUNTIF(H11:AH11,"SB") -> 1 | AT11: =SUM(AN11:AQ11)+AR11*0.5 -> 4 | AU11: =AN11*1+AO11*1.5+AP11*2.5+AQ11*2+AR11*0.5 -> 5.5 | AV11: =COUNTIFS(H11:AH11,"",$H$6:$AH$6,">5")+COUNTIFS(H11:AH11,"X",$H$6:$AH$6,">5") -> 7 | AW11: =COUNTIF(H11:AH11,"WR*") -> 0 | AX11: =AU11/AT11 -> 1.375 | AY11: =AT11+AJ11 -> 13.5 | AZ11: =AU11+AK11 -> 19.5 | BA11: =AV11+AL11 -> 26 | BB11: =AW11+AM11 -> 3 | BC11: =AZ11/AY11 -> 1.4444444
B12: =B11+1 -> 8 | C12: =C11+1 -> 5 | D12: Fong Yi Hern | E12: 55 | F12: =IFERROR(IF(VLOOKUP($D12,'Dec 25'!$D$8:$AQ$43,39,0)=0,"",VLOOKUP($D12,'Dec 25'!$D$8:$AQ$43,39,0)),"") | G12: =IFERROR(IF(VLOOKUP($D12,'Dec 25'!$D$8:$AQ$43,40,0)=0,"",VLOOKUP($D12,'Dec 25'!$D$8:$AQ$43,40,0)),"") | L12: WR2 | M12: HO5 | S12: HO6 | Y12: HO5 | AE12: SB | AH12: HO1 | AJ12: =IFERROR(VLOOKUP($D12,'Dec 25'!$D$8:$BL$43,57,0),0) -> 0 | AK12: =IFERROR(VLOOKUP($D12,'Dec 25'!$D$8:$BL$43,58,0),0) -> 0 | AL12: =IFERROR(VLOOKUP($D12,'Dec 25'!$D$8:$BL$43,59,0),0) -> 0 | AM12: =IFERROR(VLOOKUP($D12,'Dec 25'!$D$8:$BL$43,60,0),0) -> 0 | AN12: =COUNTIFS(H12:AH12,"HO*",$H$6:$AH$6,"<5") -> 2 | AO12: =COUNTIFS(H12:AH12,"HO*",$H$6:$AH$6,"5") -> 0 | AP12: =COUNTIFS(H12:AH12,"HO*",$H$6:$AH$6,"6")-COUNTIFS(H12:AH12,"HO6",$H$6:$AH$6,"6") -> 1 | AQ12: =COUNTIFS(H12:AH12,"HO*",$H$6:$AH$6,"7")-COUNTIFS(H12:AH12,"HO6",$H$6:$AH$6,"7") -> 0 | AR12: =COUNTIF(H12:AH12,"HO6") -> 1 | AS12: =COUNTIF(H12:AH12,"SB") -> 1 | AT12: =SUM(AN12:AQ12)+AR12*0.5 -> 3.5 | AU12: =AN12*1+AO12*1.5+AP12*2.5+AQ12*2+AR12*0.5 -> 5 | AV12: =COUNTIFS(H12:AH12,"",$H$6:$AH$6,">5")+COUNTIFS(H12:AH12,"X",$H$6:$AH$6,">5") -> 5 | AW12: =COUNTIF(H12:AH12,"WR*") -> 1 | AX12: =AU12/AT12 -> 1.4285714 | AY12: =AT12+AJ12 -> 3.5 | AZ12: =AU12+AK12 -> 5 | BA12: =AV12+AL12 -> 5 | BB12: =AW12+AM12 -> 1 | BC12: =AZ12/AY12 -> 1.4285714
B13: =B12+1 -> 9 | C13: =C12+1 -> 6 | D13: Ewe Zi Feng | E13: 51 | F13: =IFERROR(IF(VLOOKUP($D13,'Dec 25'!$D$8:$AQ$43,39,0)=0,"",VLOOKUP($D13,'Dec 25'!$D$8:$AQ$43,39,0)),"") | G13: =IFERROR(IF(VLOOKUP($D13,'Dec 25'!$D$8:$AQ$43,40,0)=0,"",VLOOKUP($D13,'Dec 25'!$D$8:$AQ$43,40,0)),"") | L13: HO1 | S13: WR1 | U13: HO1 | X13: HO1 | AD13: HO4 | AG13: SB | AJ13: =IFERROR(VLOOKUP($D13,'Dec 25'!$D$8:$BL$43,57,0),0) -> 0 | AK13: =IFERROR(VLOOKUP($D13,'Dec 25'!$D$8:$BL$43,58,0),0) -> 0 | AL13: =IFERROR(VLOOKUP($D13,'Dec 25'!$D$8:$BL$43,59,0),0) -> 0 | AM13: =IFERROR(VLOOKUP($D13,'Dec 25'!$D$8:$BL$43,60,0),0) -> 0 | AN13: =COUNTIFS(H13:AH13,"HO*",$H$6:$AH$6,"<5") -> 2 | AO13: =COUNTIFS(H13:AH13,"HO*",$H$6:$AH$6,"5") -> 1 | AP13: =COUNTIFS(H13:AH13,"HO*",$H$6:$AH$6,"6")-COUNTIFS(H13:AH13,"HO6",$H$6:$AH$6,"6") -> 0 | AQ13: =COUNTIFS(H13:AH13,"HO*",$H$6:$AH$6,"7")-COUNTIFS(H13:AH13,"HO6",$H$6:$AH$6,"7") -> 1 | AR13: =COUNTIF(H13:AH13,"HO6") -> 0 | AS13: =COUNTIF(H13:AH13,"SB") -> 1 | AT13: =SUM(AN13:AQ13)+AR13*0.5 -> 4 | AU13: =AN13*1+AO13*1.5+AP13*2.5+AQ13*2+AR13*0.5 -> 5.5 | AV13: =COUNTIFS(H13:AH13,"",$H$6:$AH$6,">5")+COUNTIFS(H13:AH13,"X",$H$6:$AH$6,">5") -> 5 | AW13: =COUNTIF(H13:AH13,"WR*") -> 1 | AX13: =AU13/AT13 -> 1.375 | AY13: =AT13+AJ13 -> 4 | AZ13: =AU13+AK13 -> 5.5 | BA13: =AV13+AL13 -> 5 | BB13: =AW13+AM13 -> 1 | BC13: =AZ13/AY13 -> 1.375
B14: =B13+1 -> 10 | C14: =C13+1 -> 7 | D14: Zachary Loh | E14: 51 | F14: =IFERROR(IF(VLOOKUP($D14,'Dec 25'!$D$8:$AQ$43,39,0)=0,"",VLOOKUP($D14,'Dec 25'!$D$8:$AQ$43,39,0)),"") | G14: =IFERROR(IF(VLOOKUP($D14,'Dec 25'!$D$8:$AQ$43,40,0)=0,"",VLOOKUP($D14,'Dec 25'!$D$8:$AQ$43,40,0)),"") | H14: HO1 | K14: WR1 | M14: HO1 | P14: HO4 | V14: HO1 | W14: PRE-LEAVE | X14: LEAVE | Y14: LEAVE | Z14: LEAVE | AA14: LEAVE | AB14: LEAVE | AC14: LEAVE | AD14: LEAVE | AE14: LEAVE | AF14: LEAVE | AG14: LEAVE | AH14: LEAVE | AJ14: =IFERROR(VLOOKUP($D14,'Dec 25'!$D$8:$BL$43,57,0),0) -> 15.5 | AK14: =IFERROR(VLOOKUP($D14,'Dec 25'!$D$8:$BL$43,58,0),0) -> 23 | AL14: =IFERROR(VLOOKUP($D14,'Dec 25'!$D$8:$BL$43,59,0),0) -> 20 | AM14: =IFERROR(VLOOKUP($D14,'Dec 25'!$D$8:$BL$43,60,0),0) -> 3 | AN14: =COUNTIFS(H14:AH14,"HO*",$H$6:$AH$6,"<5") -> 4 | AO14: =COUNTIFS(H14:AH14,"HO*",$H$6:$AH$6,"5") -> 0 | AP14: =COUNTIFS(H14:AH14,"HO*",$H$6:$AH$6,"6")-COUNTIFS(H14:AH14,"HO6",$H$6:$AH$6,"6") -> 0 | AQ14: =COUNTIFS(H14:AH14,"HO*",$H$6:$AH$6,"7")-COUNTIFS(H14:AH14,"HO6",$H$6:$AH$6,"7") -> 0 | AR14: =COUNTIF(H14:AH14,"HO6") -> 0 | AS14: =COUNTIF(H14:AH14,"SB") -> 0 | AT14: =SUM(AN14:AQ14)+AR14*0.5 -> 4 | AU14: =AN14*1+AO14*1.5+AP14*2.5+AQ14*2+AR14*0.5 -> 4 | AV14: =COUNTIFS(H14:AH14,"",$H$6:$AH$6,">5")+COUNTIFS(H14:AH14,"X",$H$6:$AH$6,">5") -> 3 | AW14: =COUNTIF(H14:AH14,"WR*") -> 1 | AX14: =AU14/AT14 -> 1 | AY14: =AT14+AJ14 -> 19.5 | AZ14: =AU14+AK14 -> 27 | BA14: =AV14+AL14 -> 23 | BB14: =AW14+AM14 -> 4 | BC14: =AZ14/AY14 -> 1.3846154
B15: =B14+1 -> 11 | C15: =C14+1 -> 8 | D15: Khe Jia Siang | E15: 46 | F15: =IFERROR(IF(VLOOKUP($D15,'Dec 25'!$D$8:$AQ$43,39,0)=0,"",VLOOKUP($D15,'Dec 25'!$D$8:$AQ$43,39,0)),"") | G15: =IFERROR(IF(VLOOKUP($D15,'Dec 25'!$D$8:$AQ$43,40,0)=0,"",VLOOKUP($D15,'Dec 25'!$D$8:$AQ$43,40,0)),"") | I15: HO5 | J15: PRE-LEAVE | K15: LEAVE | L15: LEAVE | M15: LEAVE | N15: LEAVE | O15: LEAVE | P15: LEAVE | Q15: LEAVE | S15: SB | W15: HO4 | AB15: HO3 | AF15: HO2 | AJ15: =IFERROR(VLOOKUP($D15,'Dec 25'!$D$8:$BL$43,57,0),0) -> 9.5 | AK15: =IFERROR(VLOOKUP($D15,'Dec 25'!$D$8:$BL$43,58,0),0) -> 14 | AL15: =IFERROR(VLOOKUP($D15,'Dec 25'!$D$8:$BL$43,59,0),0) -> 20 | AM15: =IFERROR(VLOOKUP($D15,'Dec 25'!$D$8:$BL$43,60,0),0) -> 3 | AN15: =COUNTIFS(H15:AH15,"HO*",$H$6:$AH$6,"<5") -> 3 | AO15: =COUNTIFS(H15:AH15,"HO*",$H$6:$AH$6,"5") -> 0 | AP15: =COUNTIFS(H15:AH15,"HO*",$H$6:$AH$6,"6")-COUNTIFS(H15:AH15,"HO6",$H$6:$AH$6,"6") -> 1 | AQ15: =COUNTIFS(H15:AH15,"HO*",$H$6:$AH$6,"7")-COUNTIFS(H15:AH15,"HO6",$H$6:$AH$6,"7") -> 0 | AR15: =COUNTIF(H15:AH15,"HO6") -> 0 | AS15: =COUNTIF(H15:AH15,"SB") -> 1 | AT15: =SUM(AN15:AQ15)+AR15*0.5 -> 4 | AU15: =AN15*1+AO15*1.5+AP15*2.5+AQ15*2+AR15*0.5 -> 5.5 | AV15: =COUNTIFS(H15:AH15,"",$H$6:$AH$6,">5")+COUNTIFS(H15:AH15,"X",$H$6:$AH$6,">5") -> 4 | AW15: =COUNTIF(H15:AH15,"WR*") -> 0 | AX15: =AU15/AT15 -> 1.375 | AY15: =AT15+AJ15 -> 13.5 | AZ15: =AU15+AK15 -> 19.5 | BA15: =AV15+AL15 -> 24 | BB15: =AW15+AM15 -> 3 | BC15: =AZ15/AY15 -> 1.4444444
B16: =B15+1 -> 12 | C16: =C15+1 -> 9 | D16: Sarah Chen | E16: 56 | F16: =IFERROR(IF(VLOOKUP($D16,'Dec 25'!$D$8:$AQ$43,39,0)=0,"",VLOOKUP($D16,'Dec 25'!$D$8:$AQ$43,39,0)),"") | G16: =IFERROR(IF(VLOOKUP($D16,'Dec 25'!$D$8:$AQ$43,40,0)=0,"",VLOOKUP($D16,'Dec 25'!$D$8:$AQ$43,40,0)),"") | K16: WR3 | P16: HO3 | S16: HO2 | V16: HO2 | W16: PRE-LEAVE | X16: LEAVE | Y16: LEAVE | Z16: LEAVE | AA16: LEAVE | AB16: LEAVE | AG16: HO2 | AJ16: =IFERROR(VLOOKUP($D16,'Dec 25'!$D$8:$BL$43,57,0),0) -> 0 | AK16: =IFERROR(VLOOKUP($D16,'Dec 25'!$D$8:$BL$43,58,0),0) -> 0 | AL16: =IFERROR(VLOOKUP($D16,'Dec 25'!$D$8:$BL$43,59,0),0) -> 0 | AM16: =IFERROR(VLOOKUP($D16,'Dec 25'!$D$8:$BL$43,60,0),0) -> 0 | AN16: =COUNTIFS(H16:AH16,"HO*",$H$6:$AH$6,"<5") -> 2 | AO16: =COUNTIFS(H16:AH16,"HO*",$H$6:$AH$6,"5") -> 0 | AP16: =COUNTIFS(H16:AH16,"HO*",$H$6:$AH$6,"6")-COUNTIFS(H16:AH16,"HO6",$H$6:$AH$6,"6") -> 0 | AQ16: =COUNTIFS(H16:AH16,"HO*",$H$6:$AH$6,"7")-COUNTIFS(H16:AH16,"HO6",$H$6:$AH$6,"7") -> 2 | AR16: =COUNTIF(H16:AH16,"HO6") -> 0 | AS16: =COUNTIF(H16:AH16,"SB") -> 0 | AT16: =SUM(AN16:AQ16)+AR16*0.5 -> 4 | AU16: =AN16*1+AO16*1.5+AP16*2.5+AQ16*2+AR16*0.5 -> 6 | AV16: =COUNTIFS(H16:AH16,"",$H$6:$AH$6,">5")+COUNTIFS(H16:AH16,"X",$H$6:$AH$6,">5") -> 3 | AW16: =COUNTIF(H16:AH16,"WR*") -> 1 | AX16: =AU16/AT16 -> 1.5 | AY16: =AT16+AJ16 -> 4 | AZ16: =AU16+AK16 -> 6 | BA16: =AV16+AL16 -> 3 | BB16: =AW16+AM16 -> 1 | BC16: =AZ16/AY16 -> 1.5
B17: =B16+1 -> 13 | C17: =C16+1 -> 10 | D17: Ezra Eio | E17: 56 | F17: =IFERROR(IF(VLOOKUP($D17,'Dec 25'!$D$8:$AQ$43,39,0)=0,"",VLOOKUP($D17,'Dec 25'!$D$8:$AQ$43,39,0)),"") | G17: =IFERROR(IF(VLOOKUP($D17,'Dec 25'!$D$8:$AQ$43,40,0)=0,"",VLOOKUP($D17,'Dec 25'!$D$8:$AQ$43,40,0)),"") | I17: HO2 | L17: WR3 | N17: HO2 | S17: HO3 | X17: SB | AB17: HO2 | AJ17: =IFERROR(VLOOKUP($D17,'Dec 25'!$D$8:$BL$43,57,0),0) -> 0 | AK17: =IFERROR(VLOOKUP($D17,'Dec 25'!$D$8:$BL$43,58,0),0) -> 0 | AL17: =IFERROR(VLOOKUP($D17,'Dec 25'!$D$8:$BL$43,59,0),0) -> 0 | AM17: =IFERROR(VLOOKUP($D17,'Dec 25'!$D$8:$BL$43,60,0),0) -> 0 | AN17: =COUNTIFS(H17:AH17,"HO*",$H$6:$AH$6,"<5") -> 3 | AO17: =COUNTIFS(H17:AH17,"HO*",$H$6:$AH$6,"5") -> 0 | AP17: =COUNTIFS(H17:AH17,"HO*",$H$6:$AH$6,"6")-COUNTIFS(H17:AH17,"HO6",$H$6:$AH$6,"6") -> 0 | AQ17: =COUNTIFS(H17:AH17,"HO*",$H$6:$AH$6,"7")-COUNTIFS(H17:AH17,"HO6",$H$6:$AH$6,"7") -> 1 | AR17: =COUNTIF(H17:AH17,"HO6") -> 0 | AS17: =COUNTIF(H17:AH17,"SB") -> 1 | AT17: =SUM(AN17:AQ17)+AR17*0.5 -> 4 | AU17: =AN17*1+AO17*1.5+AP17*2.5+AQ17*2+AR17*0.5 -> 5 | AV17: =COUNTIFS(H17:AH17,"",$H$6:$AH$6,">5")+COUNTIFS(H17:AH17,"X",$H$6:$AH$6,">5") -> 6 | AW17: =COUNTIF(H17:AH17,"WR*") -> 1 | AX17: =AU17/AT17 -> 1.25 | AY17: =AT17+AJ17 -> 4 | AZ17: =AU17+AK17 -> 5 | BA17: =AV17+AL17 -> 6 | BB17: =AW17+AM17 -> 1 | BC17: =AZ17/AY17 -> 1.25
B18: =B17+1 -> 14 | C18: =C17+1 -> 11 | D18: Haaroon Silmi | E18: 56 | F18: =IFERROR(IF(VLOOKUP($D18,'Dec 25'!$D$8:$AQ$43,39,0)=0,"",VLOOKUP($D18,'Dec 25'!$D$8:$AQ$43,39,0)),"") | G18: =IFERROR(IF(VLOOKUP($D18,'Dec 25'!$D$8:$AQ$43,40,0)=0,"",VLOOKUP($D18,'Dec 25'!$D$8:$AQ$43,40,0)),"") | K18: HO2 | O18: HO2 | P18: PRE-LEAVE | Q18: LEAVE | R18: LEAVE | S18: LEAVE | T18: LEAVE | U18: LEAVE | X18: HO2 | AJ18: =IFERROR(VLOOKUP($D18,'Dec 25'!$D$8:$BL$43,57,0),0) -> 0 | AK18: =IFERROR(VLOOKUP($D18,'Dec 25'!$D$8:$BL$43,58,0),0) -> 0 | AL18: =IFERROR(VLOOKUP($D18,'Dec 25'!$D$8:$BL$43,59,0),0) -> 0 | AM18: =IFERROR(VLOOKUP($D18,'Dec 25'!$D$8:$BL$43,60,0),0) -> 0 | AN18: =COUNTIFS(H18:AH18,"HO*",$H$6:$AH$6,"<5") -> 1 | AO18: =COUNTIFS(H18:AH18,"HO*",$H$6:$AH$6,"5") -> 1 | AP18: =COUNTIFS(H18:AH18,"HO*",$H$6:$AH$6,"6")-COUNTIFS(H18:AH18,"HO6",$H$6:$AH$6,"6") -> 1 | AQ18: =COUNTIFS(H18:AH18,"HO*",$H$6:$AH$6,"7")-COUNTIFS(H18:AH18,"HO6",$H$6:$AH$6,"7") -> 0 | AR18: =COUNTIF(H18:AH18,"HO6") -> 0 | AS18: =COUNTIF(H18:AH18,"SB") -> 0 | AT18: =SUM(AN18:AQ18)+AR18*0.5 -> 3 | AU18: =AN18*1+AO18*1.5+AP18*2.5+AQ18*2+AR18*0.5 -> 5 | AV18: =COUNTIFS(H18:AH18,"",$H$6:$AH$6,">5")+COUNTIFS(H18:AH18,"X",$H$6:$AH$6,">5") -> 5 | AW18: =COUNTIF(H18:AH18,"WR*") -> 0 | AX18: =AU18/AT18 -> 1.6666667 | AY18: =AT18+AJ18 -> 3 | AZ18: =AU18+AK18 -> 5 | BA18: =AV18+AL18 -> 5 | BB18: =AW18+AM18 -> 0 | BC18: =AZ18/AY18 -> 1.6666667
B19: =B18+1 -> 15 | C19: =C18+1 -> 12 | D19: Lim Jieyu | E19: 56 | F19: =IFERROR(IF(VLOOKUP($D19,'Dec 25'!$D$8:$AQ$43,39,0)=0,"",VLOOKUP($D19,'Dec 25'!$D$8:$AQ$43,39,0)),"") | G19: =IFERROR(IF(VLOOKUP($D19,'Dec 25'!$D$8:$AQ$43,40,0)=0,"",VLOOKUP($D19,'Dec 25'!$D$8:$AQ$43,40,0)),"") | J19: HO2 | N19: HO1 | R19: WR3 | W19: HO2 | Z19: HO2 | AF19: SB | AJ19: =IFERROR(VLOOKUP($D19,'Dec 25'!$D$8:$BL$43,57,0),0) -> 0 | AK19: =IFERROR(VLOOKUP($D19,'Dec 25'!$D$8:$BL$43,58,0),0) -> 0 | AL19: =IFERROR(VLOOKUP($D19,'Dec 25'!$D$8:$BL$43,59,0),0) -> 0 | AM19: =IFERROR(VLOOKUP($D19,'Dec 25'!$D$8:$BL$43,60,0),0) -> 0 | AN19: =COUNTIFS(H19:AH19,"HO*",$H$6:$AH$6,"<5") -> 2 | AO19: =COUNTIFS(H19:AH19,"HO*",$H$6:$AH$6,"5") -> 1 | AP19: =COUNTIFS(H19:AH19,"HO*",$H$6:$AH$6,"6")-COUNTIFS(H19:AH19,"HO6",$H$6:$AH$6,"6") -> 0 | AQ19: =COUNTIFS(H19:AH19,"HO*",$H$6:$AH$6,"7")-COUNTIFS(H19:AH19,"HO6",$H$6:$AH$6,"7") -> 1 | AR19: =COUNTIF(H19:AH19,"HO6") -> 0 | AS19: =COUNTIF(H19:AH19,"SB") -> 1 | AT19: =SUM(AN19:AQ19)+AR19*0.5 -> 4 | AU19: =AN19*1+AO19*1.5+AP19*2.5+AQ19*2+AR19*0.5 -> 5.5 | AV19: =COUNTIFS(H19:AH19,"",$H$6:$AH$6,">5")+COUNTIFS(H19:AH19,"X",$H$6:$AH$6,">5") -> 5 | AW19: =COUNTIF(H19:AH19,"WR*") -> 1 | AX19: =AU19/AT19 -> 1.375 | AY19: =AT19+AJ19 -> 4 | AZ19: =AU19+AK19 -> 5.5 | BA19: =AV19+AL19 -> 5 | BB19: =AW19+AM19 -> 1 | BC19: =AZ19/AY19 -> 1.375
B20: =B19+1 -> 16 | C20: =C19+1 -> 13 | D20: Angeline Ong | E20: 56 | F20: =IFERROR(IF(VLOOKUP($D20,'Dec 25'!$D$8:$AQ$43,39,0)=0,"",VLOOKUP($D20,'Dec 25'!$D$8:$AQ$43,39,0)),"") | G20: =IFERROR(IF(VLOOKUP($D20,'Dec 25'!$D$8:$AQ$43,40,0)=0,"",VLOOKUP($D20,'Dec 25'!$D$8:$AQ$43,40,0)),"") | H20: HO2 | N20: HO5 | R20: HO2 | V20: SB | X20: LEAVE | Y20: LEAVE | Z20: LEAVE | AA20: LEAVE | AC20: HO2 | AG20: WR3 | AJ20: =IFERROR(VLOOKUP($D20,'Dec 25'!$D$8:$BL$43,57,0),0) -> 0 | AK20: =IFERROR(VLOOKUP($D20,'Dec 25'!$D$8:$BL$43,58,0),0) -> 0 | AL20: =IFERROR(VLOOKUP($D20,'Dec 25'!$D$8:$BL$43,59,0),0) -> 0 | AM20: =IFERROR(VLOOKUP($D20,'Dec 25'!$D$8:$BL$43,60,0),0) -> 0 | AN20: =COUNTIFS(H20:AH20,"HO*",$H$6:$AH$6,"<5") -> 3 | AO20: =COUNTIFS(H20:AH20,"HO*",$H$6:$AH$6,"5") -> 0 | AP20: =COUNTIFS(H20:AH20,"HO*",$H$6:$AH$6,"6")-COUNTIFS(H20:AH20,"HO6",$H$6:$AH$6,"6") -> 1 | AQ20: =COUNTIFS(H20:AH20,"HO*",$H$6:$AH$6,"7")-COUNTIFS(H20:AH20,"HO6",$H$6:$AH$6,"7") -> 0 | AR20: =COUNTIF(H20:AH20,"HO6") -> 0 | AS20: =COUNTIF(H20:AH20,"SB") -> 1 | AT20: =SUM(AN20:AQ20)+AR20*0.5 -> 4 | AU20: =AN20*1+AO20*1.5+AP20*2.5+AQ20*2+AR20*0.5 -> 5.5 | AV20: =COUNTIFS(H20:AH20,"",$H$6:$AH$6,">5")+COUNTIFS(H20:AH20,"X",$H$6:$AH$6,">5") -> 4 | AW20: =COUNTIF(H20:AH20,"WR*") -> 1 | AX20: =AU20/AT20 -> 1.375 | AY20: =AT20+AJ20 -> 4 | AZ20: =AU20+AK20 -> 5.5 | BA20: =AV20+AL20 -> 4 | BB20: =AW20+AM20 -> 1 | BC20: =AZ20/AY20 -> 1.375
B21: =B20+1 -> 17 | C21: =C20+1 -> 14 | D21: Chermaine Seah | E21: 85 | F21: =IFERROR(IF(VLOOKUP($D21,'Dec 25'!$D$8:$AQ$43,39,0)=0,"",VLOOKUP($D21,'Dec 25'!$D$8:$AQ$43,39,0)),"") | G21: =IFERROR(IF(VLOOKUP($D21,'Dec 25'!$D$8:$AQ$43,40,0)=0,"",VLOOKUP($D21,'Dec 25'!$D$8:$AQ$43,40,0)),"") | J21: HO1 | P21: HO2 | S21: WR3 | T21: SB | Y21: HO2 | AD21: HO2 | AJ21: =IFERROR(VLOOKUP($D21,'Dec 25'!$D$8:$BL$43,57,0),0) -> 0 | AK21: =IFERROR(VLOOKUP($D21,'Dec 25'!$D$8:$BL$43,58,0),0) -> 0 | AL21: =IFERROR(VLOOKUP($D21,'Dec 25'!$D$8:$BL$43,59,0),0) -> 0 | AM21: =IFERROR(VLOOKUP($D21,'Dec 25'!$D$8:$BL$43,60,0),0) -> 0 | AN21: =COUNTIFS(H21:AH21,"HO*",$H$6:$AH$6,"<5") -> 2 | AO21: =COUNTIFS(H21:AH21,"HO*",$H$6:$AH$6,"5") -> 1 | AP21: =COUNTIFS(H21:AH21,"HO*",$H$6:$AH$6,"6")-COUNTIFS(H21:AH21,"HO6",$H$6:$AH$6,"6") -> 1 | AQ21: =COUNTIFS(H21:AH21,"HO*",$H$6:$AH$6,"7")-COUNTIFS(H21:AH21,"HO6",$H$6:$AH$6,"7") -> 0 | AR21: =COUNTIF(H21:AH21,"HO6") -> 0 | AS21: =COUNTIF(H21:AH21,"SB") -> 1 | AT21: =SUM(AN21:AQ21)+AR21*0.5 -> 4 | AU21: =AN21*1+AO21*1.5+AP21*2.5+AQ21*2+AR21*0.5 -> 6 | AV21: =COUNTIFS(H21:AH21,"",$H$6:$AH$6,">5")+COUNTIFS(H21:AH21,"X",$H$6:$AH$6,">5") -> 6 | AW21: =COUNTIF(H21:AH21,"WR*") -> 1 | AX21: =AU21/AT21 -> 1.5 | AY21: =AT21+AJ21 -> 4 | AZ21: =AU21+AK21 -> 6 | BA21: =AV21+AL21 -> 6 | BB21: =AW21+AM21 -> 1 | BC21: =AZ21/AY21 -> 1.5
B22: =B21+1 -> 18 | C22: =C21+1 -> 15 | D22: Lee Jia Wei | E22: 85 | F22: =IFERROR(IF(VLOOKUP($D22,'Dec 25'!$D$8:$AQ$43,39,0)=0,"",VLOOKUP($D22,'Dec 25'!$D$8:$AQ$43,39,0)),"") | G22: =IFERROR(IF(VLOOKUP($D22,'Dec 25'!$D$8:$AQ$43,40,0)=0,"",VLOOKUP($D22,'Dec 25'!$D$8:$AQ$43,40,0)),"") | I22: SB | L22: HO2 | Q22: HO2 | U22: HO2 | AC22: HO3 | AJ22: =IFERROR(VLOOKUP($D22,'Dec 25'!$D$8:$BL$43,57,0),0) -> 0 | AK22: =IFERROR(VLOOKUP($D22,'Dec 25'!$D$8:$BL$43,58,0),0) -> 0 | AL22: =IFERROR(VLOOKUP($D22,'Dec 25'!$D$8:$BL$43,59,0),0) -> 0 | AM22: =IFERROR(VLOOKUP($D22,'Dec 25'!$D$8:$BL$43,60,0),0) -> 0 | AN22: =COUNTIFS(H22:AH22,"HO*",$H$6:$AH$6,"<5") -> 2 | AO22: =COUNTIFS(H22:AH22,"HO*",$H$6:$AH$6,"5") -> 1 | AP22: =COUNTIFS(H22:AH22,"HO*",$H$6:$AH$6,"6")-COUNTIFS(H22:AH22,"HO6",$H$6:$AH$6,"6") -> 0 | AQ22: =COUNTIFS(H22:AH22,"HO*",$H$6:$AH$6,"7")-COUNTIFS(H22:AH22,"HO6",$H$6:$AH$6,"7") -> 1 | AR22: =COUNTIF(H22:AH22,"HO6") -> 0 | AS22: =COUNTIF(H22:AH22,"SB") -> 1 | AT22: =SUM(AN22:AQ22)+AR22*0.5 -> 4 | AU22: =AN22*1+AO22*1.5+AP22*2.5+AQ22*2+AR22*0.5 -> 5.5 | AV22: =COUNTIFS(H22:AH22,"",$H$6:$AH$6,">5")+COUNTIFS(H22:AH22,"X",$H$6:$AH$6,">5") -> 7 | AW22: =COUNTIF(H22:AH22,"WR*") -> 0 | AX22: =AU22/AT22 -> 1.375 | AY22: =AT22+AJ22 -> 4 | AZ22: =AU22+AK22 -> 5.5 | BA22: =AV22+AL22 -> 7 | BB22: =AW22+AM22 -> 0 | BC22: =AZ22/AY22 -> 1.375
B23: =B22+1 -> 19 | C23: =C22+1 -> 16 | D23: Tasha Anna Leow | E23: 66 | F23: =IFERROR(IF(VLOOKUP($D23,'Dec 25'!$D$8:$AQ$43,39,0)=0,"",VLOOKUP($D23,'Dec 25'!$D$8:$AQ$43,39,0)),"") | G23: =IFERROR(IF(VLOOKUP($D23,'Dec 25'!$D$8:$AQ$43,40,0)=0,"",VLOOKUP($D23,'Dec 25'!$D$8:$AQ$43,40,0)),"") | K23: HO3 | O23: SB | V23: PRE-LEAVE | W23: LEAVE | X23: LEAVE | AA23: HO2 | AE23: HO3 | AG23: WR2 | AJ23: =IFERROR(VLOOKUP($D23,'Dec 25'!$D$8:$BL$43,57,0),0) -> 0 | AK23: =IFERROR(VLOOKUP($D23,'Dec 25'!$D$8:$BL$43,58,0),0) -> 0 | AL23: =IFERROR(VLOOKUP($D23,'Dec 25'!$D$8:$BL$43,59,0),0) -> 0 | AM23: =IFERROR(VLOOKUP($D23,'Dec 25'!$D$8:$BL$43,60,0),0) -> 0 | AN23: =COUNTIFS(H23:AH23,"HO*",$H$6:$AH$6,"<5") -> 1 | AO23: =COUNTIFS(H23:AH23,"HO*",$H$6:$AH$6,"5") -> 1 | AP23: =COUNTIFS(H23:AH23,"HO*",$H$6:$AH$6,"6")-COUNTIFS(H23:AH23,"HO6",$H$6:$AH$6,"6") -> 1 | AQ23: =COUNTIFS(H23:AH23,"HO*",$H$6:$AH$6,"7")-COUNTIFS(H23:AH23,"HO6",$H$6:$AH$6,"7") -> 0 | AR23: =COUNTIF(H23:AH23,"HO6") -> 0 | AS23: =COUNTIF(H23:AH23,"SB") -> 1 | AT23: =SUM(AN23:AQ23)+AR23*0.5 -> 3 | AU23: =AN23*1+AO23*1.5+AP23*2.5+AQ23*2+AR23*0.5 -> 5 | AV23: =COUNTIFS(H23:AH23,"",$H$6:$AH$6,">5")+COUNTIFS(H23:AH23,"X",$H$6:$AH$6,">5") -> 6 | AW23: =COUNTIF(H23:AH23,"WR*") -> 1 | AX23: =AU23/AT23 -> 1.6666667 | AY23: =AT23+AJ23 -> 3 | AZ23: =AU23+AK23 -> 5 | BA23: =AV23+AL23 -> 6 | BB23: =AW23+AM23 -> 1 | BC23: =AZ23/AY23 -> 1.6666667
B24: =B23+1 -> 20 | C24: =C23+1 -> 17 | D24: Brendon Loo | E24: 66 | F24: =IFERROR(IF(VLOOKUP($D24,'Dec 25'!$D$8:$AQ$43,39,0)=0,"",VLOOKUP($D24,'Dec 25'!$D$8:$AQ$43,39,0)),"") | G24: =IFERROR(IF(VLOOKUP($D24,'Dec 25'!$D$8:$AQ$43,40,0)=0,"",VLOOKUP($D24,'Dec 25'!$D$8:$AQ$43,40,0)),"") | H24: HO3 | L24: HO3 | Q24: HO3 | U24: HO3 | Y24: HO6 | AC24: LEAVE | AD24: LEAVE | AE24: LEAVE | AF24: LEAVE | AG24: LEAVE | AH24: LEAVE | AJ24: =IFERROR(VLOOKUP($D24,'Dec 25'!$D$8:$BL$43,57,0),0) -> 0 | AK24: =IFERROR(VLOOKUP($D24,'Dec 25'!$D$8:$BL$43,58,0),0) -> 0 | AL24: =IFERROR(VLOOKUP($D24,'Dec 25'!$D$8:$BL$43,59,0),0) -> 0 | AM24: =IFERROR(VLOOKUP($D24,'Dec 25'!$D$8:$BL$43,60,0),0) -> 0 | AN24: =COUNTIFS(H24:AH24,"HO*",$H$6:$AH$6,"<5") -> 2 | AO24: =COUNTIFS(H24:AH24,"HO*",$H$6:$AH$6,"5") -> 1 | AP24: =COUNTIFS(H24:AH24,"HO*",$H$6:$AH$6,"6")-COUNTIFS(H24:AH24,"HO6",$H$6:$AH$6,"6") -> 0 | AQ24: =COUNTIFS(H24:AH24,"HO*",$H$6:$AH$6,"7")-COUNTIFS(H24:AH24,"HO6",$H$6:$AH$6,"7") -> 1 | AR24: =COUNTIF(H24:AH24,"HO6") -> 1 | AS24: =COUNTIF(H24:AH24,"SB") -> 0 | AT24: =SUM(AN24:AQ24)+AR24*0.5 -> 4.5 | AU24: =AN24*1+AO24*1.5+AP24*2.5+AQ24*2+AR24*0.5 -> 6 | AV24: =COUNTIFS(H24:AH24,"",$H$6:$AH$6,">5")+COUNTIFS(H24:AH24,"X",$H$6:$AH$6,">5") -> 4 | AW24: =COUNTIF(H24:AH24,"WR*") -> 0 | AX24: =AU24/AT24 -> 1.3333333 | AY24: =AT24+AJ24 -> 4.5 | AZ24: =AU24+AK24 -> 6 | BA24: =AV24+AL24 -> 4 | BB24: =AW24+AM24 -> 0 | BC24: =AZ24/AY24 -> 1.3333333
